Workbook
Name TAX: #REF!

Sheet Header
D2: Batch | E2: 20250816
D3: Batch Desc | E3: Mastercard Invoices (August 2025)
D4: Reference | E4: MC-250816
D5: Document Date | E5: 45885
D6: Posting Date | E6: =E5 -> 45885
E13: LOG IN DETAILS
D15: User | E15: eTimesheet User
D16: Password | E16: gekko

Sheet T Bell
A1: Employee to code & narrate | J1: To be copied in to pronto
J2: Credit card Statement TOTAL | K2: 3402.27
J3: Subtotal | K3: =SUM(M9:M144) -> 3402.27
A4: T Bell | J4: Variance Check | K4: =K2-K3 -> 0
A5: Reference | B5: =CONCATENATE(Header!$E$4,"Bell") -> MC-250816Bell | J5: EMPLOYEES DO NOT CHANGE
A6: Document Date | B6: =Header!$E$5 -> 45885 | E6: Credit card holder to add details
A8: Date | B8: Narrative | C8: Debit Amount | D8: Credit Amount | E8: Description | F8: Project No | G8: Cost Category | H8: GL account | J8: Account | K8: Reference | L8: Tax | M8: Amount | N8: Tax CODE | O8: TAX Amount (leave blank) | P8: CBS - Only if required | R8: limit 56charaters
A9: 45877 | B9: BELMONTS CAFE BELMONT AUS | C9: 108 | E9: Food for Lunch and Learn with GR Engineering | F9: 1084 | G9: ENFN | J9: =IF(F9>0,(_xlfn.CONCAT(F9,".",G9)),H9) -> 1084.ENFN | K9: =_xlfn.CONCAT("T Bell-",(LEFT(B9,15)),"-",E9) -> T Bell-BELMONTS CAFE B-Food for Lunch and Learn with GR Engineering | L9: I | M9: =IF(C9>0,C9,-D9) -> 108 | N9: T | Q9: CBS - needs to be pasted seperately | R9: =LEN(K9) -> 67
A10: 45876 | B10: BP GOLDEN GATE 1896 KALGOORLIE AUS | C10: 105.26 | E10: Diggers and Dealers - Petrol | F10: G077 | G10: SALP | J10: =IF(F10>0,(_xlfn.CONCAT(F10,".",G10)),H10) -> G077.SALP | K10: =_xlfn.CONCAT("T Bell-",(LEFT(B10,15)),"-",E10) -> T Bell-BP GOLDEN GATE -Diggers and Dealers - Petrol | L10: I | M10: =IF(C10>0,C10,-D10) -> 105.26 | N10: T | R10: =LEN(K10) -> 52
A11: 45876 | B11: BP STHERN CROS1932 SOUTHERN CR AUS | C11: 17.9 | E11: Diggers and Dealers - Food / Amenities | F11: G077 | G11: SALP | J11: =IF(F11>0,(_xlfn.CONCAT(F11,".",G11)),H11) -> G077.SALP | K11: =_xlfn.CONCAT("T Bell-",(LEFT(B11,15)),"-",E11) -> T Bell-BP STHERN CROS1-Diggers and Dealers - Food / Amenities | L11: I | M11: =IF(C11>0,C11,-D11) -> 17.9 | N11: T | R11: =LEN(K11) -> 61
A12: 45869 | B12: CHILDRENS MEDICAL RESE WESTMEAD AUS | C12: 27.81 | E12: Lycopodium Jeans for Genes - Extra Seat Charity Dinner | F12: 1041 | G12: CONF | J12: =IF(F12>0,(_xlfn.CONCAT(F12,".",G12)),H12) -> 1041.CONF | K12: =_xlfn.CONCAT("T Bell-",(LEFT(B12,15)),"-",E12) -> T Bell-CHILDRENS MEDIC-Lycopodium Jeans for Genes - Extra Seat Charity Dinner | L12: I | M12: =IF(C12>0,C12,-D12) -> 27.81 | N12: T | R12: =LEN(K12) -> 77
A13: 45879 | B13: DELAWARE NORTH RETAQPS REDCLIFFE AUS | C13: 6.9 | E13: Ballarat Sales Conference - Food / Amenities | F13: G068 | G13: SALP | J13: =IF(F13>0,(_xlfn.CONCAT(F13,".",G13)),H13) -> G068.SALP | K13: =_xlfn.CONCAT("T Bell-",(LEFT(B13,15)),"-",E13) -> T Bell-DELAWARE NORTH -Ballarat Sales Conference - Food / Amenities | L13: I | M13: =IF(C13>0,C13,-D13) -> 6.9 | N13: T | R13: =LEN(K13) -> 67
A14: 45873 | B14: Exchange Hotel Kalgoorlie AUS | C14: 211.63 | E14: Diggers and Dealers - Food / Amenities | F14: G077 | G14: SALP | J14: =IF(F14>0,(_xlfn.CONCAT(F14,".",G14)),H14) -> G077.SALP | K14: =_xlfn.CONCAT("T Bell-",(LEFT(B14,15)),"-",E14) -> T Bell-Exchange Hotel -Diggers and Dealers - Food / Amenities | L14: I | M14: =IF(C14>0,C14,-D14) -> 211.63 | N14: T | R14: =LEN(K14) -> 61
A15: 45855 | B15: FIBBER MCGEE 'S LEEDERVILLE AUS | C15: =26/2 -> 13 | E15: Catch up with Steffen, re testwork | F15: 1084 | G15: ENFE | J15: =IF(F15>0,(_xlfn.CONCAT(F15,".",G15)),H15) -> 1084.ENFE | K15: =_xlfn.CONCAT("T Bell-",(LEFT(B15,15)),"-",E15) -> T Bell-FIBBER MCGEE 'S-Catch up with Steffen, re testwork | L15: I | M15: =IF(C15>0,C15,-D15) -> 13 | N15: T | R15: =LEN(K15) -> 57
A16: 45855 | B16: FIBBER MCGEE 'S LEEDERVILLE AUS | C16: =26/2 -> 13 | E16: Catch up with Steffen, re testwork | F16: 1084 | G16: ENFN | J16: =IF(F16>0,(_xlfn.CONCAT(F16,".",G16)),H16) -> 1084.ENFN | K16: =_xlfn.CONCAT("T Bell-",(LEFT(B16,15)),"-",E16) -> T Bell-FIBBER MCGEE 'S-Catch up with Steffen, re testwork | L16: I | M16: =IF(C16>0,C16,-D16) -> 13 | N16: T | R16: =LEN(K16) -> 57
A17: 45854 | B17: GASTECH AUSTRALIA WANGARA AUS | C17: 907.5 | E17: 1 x HCN Detctor Service and 1 x new HCN Detector | F17: 1041 | G17: SPPE | J17: =IF(F17>0,(_xlfn.CONCAT(F17,".",G17)),H17) -> 1041.SPPE | K17: =_xlfn.CONCAT("T Bell-",(LEFT(B17,15)),"-",E17) -> T Bell-GASTECH AUSTRAL-1 x HCN Detctor Service and 1 x new HCN Detector | L17: I | M17: =IF(C17>0,C17,-D17) -> 907.5 | N17: T | R17: =LEN(K17) -> 71
A18: 45867 | B18: GOOD GROCER L0030 LEEDERVILLE AUS | C18: 19.48 | E18: Wednesday Lunch | F18: 1084 | G18: ENON | J18: =IF(F18>0,(_xlfn.CONCAT(F18,".",G18)),H18) -> 1084.ENON | K18: =_xlfn.CONCAT("T Bell-",(LEFT(B18,15)),"-",E18) -> T Bell-GOOD GROCER -Wednesday Lunch | L18: I | M18: =IF(C18>0,C18,-D18) -> 19.48 | N18: T | R18: =LEN(K18) -> 38
A19: 45859 | B19: GOOD GROCER L0030 LEEDERVILLE AUS | C19: 16.89 | E19: Coffee / Sugar | F19: 1084 | G19: STAF | J19: =IF(F19>0,(_xlfn.CONCAT(F19,".",G19)),H19) -> 1084.STAF | K19: =_xlfn.CONCAT("T Bell-",(LEFT(B19,15)),"-",E19) -> T Bell-GOOD GROCER -Coffee / Sugar | L19: I | M19: =IF(C19>0,C19,-D19) -> 16.89 | N19: T | R19: =LEN(K19) -> 37
A20: 45879 | B20: GRILL'D BALLARAT BALLARAT AUS | C20: 51.7 | E20: Ballarat Sales Conference - Food / Amenities | F20: G068 | G20: SALP | J20: =IF(F20>0,(_xlfn.CONCAT(F20,".",G20)),H20) -> G068.SALP | K20: =_xlfn.CONCAT("T Bell-",(LEFT(B20,15)),"-",E20) -> T Bell-GRILL'D BALLARA-Ballarat Sales Conference - Food / Amenities | L20: I | M20: =IF(C20>0,C20,-D20) -> 51.7 | N20: T | R20: =LEN(K20) -> 67
A21: 45860 | B21: GRILLD PTY LTD - LEEDE LEEDERVILLE AUS | C21: 89 | E21: Wednesday Lunch | F21: 1041 | G21: ENON | J21: =IF(F21>0,(_xlfn.CONCAT(F21,".",G21)),H21) -> 1041.ENON | K21: =_xlfn.CONCAT("T Bell-",(LEFT(B21,15)),"-",E21) -> T Bell-GRILLD PTY LTD -Wednesday Lunch | L21: I | M21: =IF(C21>0,C21,-D21) -> 89 | N21: T | R21: =LEN(K21) -> 38
A22: 45869 | B22: Kwik Kopy Canning Vale Canning Val AUS | C22: 165.33 | E22: Diggers and Dealers - Modular Plant Brochures | F22: G077 | G22: SALP | J22: =IF(F22>0,(_xlfn.CONCAT(F22,".",G22)),H22) -> G077.SALP | K22: =_xlfn.CONCAT("T Bell-",(LEFT(B22,15)),"-",E22) -> T Bell-Kwik Kopy Canni-Diggers and Dealers - Modular Plant Brochures | L22: I | M22: =IF(C22>0,C22,-D22) -> 165.33 | N22: T | R22: =LEN(K22) -> 68
A23: 45861 | B23: Kwik Kopy Canning Vale Canning Val AUS | C23: 807.83 | E23: Diggers and Dealers - Flyers for Stachels | F23: G077 | G23: SALP | J23: =IF(F23>0,(_xlfn.CONCAT(F23,".",G23)),H23) -> G077.SALP | K23: =_xlfn.CONCAT("T Bell-",(LEFT(B23,15)),"-",E23) -> T Bell-Kwik Kopy Canni-Diggers and Dealers - Flyers for Stachels | L23: I | M23: =IF(C23>0,C23,-D23) -> 807.83 | N23: T | R23: =LEN(K23) -> 64
A24: 45856 | B24: LEEDERVILLE MINI MAR LEEDERVILLE AUS | C24: 3.98 | E24: Milk | F24: 1084 | G24: STAF | J24: =IF(F24>0,(_xlfn.CONCAT(F24,".",G24)),H24) -> 1084.STAF | K24: =_xlfn.CONCAT("T Bell-",(LEFT(B24,15)),"-",E24) -> T Bell-LEEDERVILLE MIN-Milk | L24: I | M24: =IF(C24>0,C24,-D24) -> 3.98 | N24: T | R24: =LEN(K24) -> 27
A25: 45869 | B25: LENA'S BAR Perth AUS | C25: =64.96/2 -> 32.48 | E25: Lunch with Emily at Woodside | F25: 1084 | G25: ENFE | J25: =IF(F25>0,(_xlfn.CONCAT(F25,".",G25)),H25) -> 1084.ENFE | K25: =_xlfn.CONCAT("T Bell-",(LEFT(B25,15)),"-",E25) -> T Bell-LENA'S BAR Pert-Lunch with Emily at Woodside | L25: I | M25: =IF(C25>0,C25,-D25) -> 32.48 | N25: T | R25: =LEN(K25) -> 51
A26: 45869 | B26: LENA'S BAR Perth AUS | C26: =64.96/2 -> 32.48 | E26: Lunch with Emily at Woodside | F26: 1084 | G26: ENFN | J26: =IF(F26>0,(_xlfn.CONCAT(F26,".",G26)),H26) -> 1084.ENFN | K26: =_xlfn.CONCAT("T Bell-",(LEFT(B26,15)),"-",E26) -> T Bell-LENA'S BAR Pert-Lunch with Emily at Woodside | M26: =IF(C26>0,C26,-D26) -> 32.48 | N26: T | R26: =LEN(K26) -> 51
A27: 45867 | B27: LOUVE PERTH AUS | C27: =10.5/2 -> 5.25 | E27: Coffee with Darren Athies - Ramelius | F27: 1084 | G27: ENFE | J27: =IF(F27>0,(_xlfn.CONCAT(F27,".",G27)),H27) -> 1084.ENFE | K27: =_xlfn.CONCAT("T Bell-",(LEFT(B27,15)),"-",E27) -> T Bell-LOUVE PERTH AUS-Coffee with Darren Athies - Ramelius | L27: I | M27: =IF(C27>0,C27,-D27) -> 5.25 | N27: T | R27: =LEN(K27) -> 59
A28: 45867 | B28: LOUVE PERTH AUS | C28: =10.5/2 -> 5.25 | E28: Coffee with Darren Athies - Ramelius | F28: 1084 | G28: ENFN | J28: =IF(F28>0,(_xlfn.CONCAT(F28,".",G28)),H28) -> 1084.ENFN | K28: =_xlfn.CONCAT("T Bell-",(LEFT(B28,15)),"-",E28) -> T Bell-LOUVE PERTH AUS-Coffee with Darren Athies - Ramelius | M28: =IF(C28>0,C28,-D28) -> 5.25 | N28: T | R28: =LEN(K28) -> 59
A29: 45883 | B29: MCDONALDS WENDOUREE WENDOUREE AUS | C29: 9.7 | E29: Ballarat Sales Conference - Food / Amenities | F29: G068 | G29: SALP | J29: =IF(F29>0,(_xlfn.CONCAT(F29,".",G29)),H29) -> G068.SALP | K29: =_xlfn.CONCAT("T Bell-",(LEFT(B29,15)),"-",E29) -> T Bell-MCDONALDS WENDO-Ballarat Sales Conference - Food / Amenities | L29: I | M29: =IF(C29>0,C29,-D29) -> 9.7 | N29: T | R29: =LEN(K29) -> 67
A30: 45882 | B30: MCDONALDS WENDOUREE WENDOUREE AUS | C30: 9.7 | E30: Ballarat Sales Conference - Food / Amenities | F30: G068 | G30: SALP | J30: =IF(F30>0,(_xlfn.CONCAT(F30,".",G30)),H30) -> G068.SALP | K30: =_xlfn.CONCAT("T Bell-",(LEFT(B30,15)),"-",E30) -> T Bell-MCDONALDS WENDO-Ballarat Sales Conference - Food / Amenities | L30: I | M30: =IF(C30>0,C30,-D30) -> 9.7 | N30: T | R30: =LEN(K30) -> 67
A31: 45881 | B31: MCDONALDS WENDOUREE WENDOUREE AUS | C31: 15.8 | E31: Ballarat Sales Conference - Food / Amenities | F31: G068 | G31: SALP | J31: =IF(F31>0,(_xlfn.CONCAT(F31,".",G31)),H31) -> G068.SALP | K31: =_xlfn.CONCAT("T Bell-",(LEFT(B31,15)),"-",E31) -> T Bell-MCDONALDS WENDO-Ballarat Sales Conference - Food / Amenities | L31: I | M31: =IF(C31>0,C31,-D31) -> 15.8 | N31: T | R31: =LEN(K31) -> 67
A32: 45880 | B32: MCDONALDS WENDOUREE WENDOUREE AUS | C32: 9.7 | E32: Ballarat Sales Conference - Food / Amenities | F32: G068 | G32: SALP | J32: =IF(F32>0,(_xlfn.CONCAT(F32,".",G32)),H32) -> G068.SALP | K32: =_xlfn.CONCAT("T Bell-",(LEFT(B32,15)),"-",E32) -> T Bell-MCDONALDS WENDO-Ballarat Sales Conference - Food / Amenities | L32: I | M32: =IF(C32>0,C32,-D32) -> 9.7 | N32: T | R32: =LEN(K32) -> 67
A33: 45881 | B33: North Star Hotel SOLDIERS HI AUS | C33: 156.88 | E33: Ballarat Sales Conference - Food / Amenities | F33: G068 | G33: SALP | J33: =IF(F33>0,(_xlfn.CONCAT(F33,".",G33)),H33) -> G068.SALP | K33: =_xlfn.CONCAT("T Bell-",(LEFT(B33,15)),"-",E33) -> T Bell-North Star Hote-Ballarat Sales Conference - Food / Amenities | L33: I | M33: =IF(C33>0,C33,-D33) -> 156.88 | N33: T | R33: =LEN(K33) -> 67
A34: 45874 | B34: PALACE HOTEL KALGOORL Kalgoorlie AUS | C34: 13.95 | E34: Diggers and Dealers - Food / Amenities | F34: G077 | G34: SALP | J34: =IF(F34>0,(_xlfn.CONCAT(F34,".",G34)),H34) -> G077.SALP | K34: =_xlfn.CONCAT("T Bell-",(LEFT(B34,15)),"-",E34) -> T Bell-PALACE HOTEL KA-Diggers and Dealers - Food / Amenities | L34: I | M34: =IF(C34>0,C34,-D34) -> 13.95 | N34: T | R34: =LEN(K34) -> 61
A35: 45874 | B35: PALACE HOTEL KALGOORL Kalgoorlie AUS | C35: 51.16 | E35: Diggers and Dealers - Food / Amenities | F35: G077 | G35: SALP | J35: =IF(F35>0,(_xlfn.CONCAT(F35,".",G35)),H35) -> G077.SALP | K35: =_xlfn.CONCAT("T Bell-",(LEFT(B35,15)),"-",E35) -> T Bell-PALACE HOTEL KA-Diggers and Dealers - Food / Amenities | L35: I | M35: =IF(C35>0,C35,-D35) -> 51.16 | N35: T | R35: =LEN(K35) -> 61
A36: 45866 | B36: ROSSMOYNE IGA ROSSMOYNE AUS | C36: 6.49 | E36: Coffee | F36: 1084 | G36: STAF | J36: =IF(F36>0,(_xlfn.CONCAT(F36,".",G36)),H36) -> 1084.STAF | K36: =_xlfn.CONCAT("T Bell-",(LEFT(B36,15)),"-",E36) -> T Bell-ROSSMOYNE IGA R-Coffee | L36: I | M36: =IF(C36>0,C36,-D36) -> 6.49 | N36: T | R36: =LEN(K36) -> 31
A37: 45877 | B37: SQ *NOURISH KITCHEN & Leederville AUS | C37: 15.9 | E37: Wednesday Lunch | F37: 1084 | G37: ENON | J37: =IF(F37>0,(_xlfn.CONCAT(F37,".",G37)),H37) -> 1084.ENON | K37: =_xlfn.CONCAT("T Bell-",(LEFT(B37,15)),"-",E37) -> T Bell-SQ *NOURISH KIT-Wednesday Lunch | L37: I | M37: =IF(C37>0,C37,-D37) -> 15.9 | N37: T | R37: =LEN(K37) -> 38
A38: 45880 | B38: THE CITY OVAL HOTEL BA BALLARAT CE AUS | C38: 25.07 | E38: Ballarat Sales Conference - Food / Amenities | F38: G068 | G38: SALP | J38: =IF(F38>0,(_xlfn.CONCAT(F38,".",G38)),H38) -> G068.SALP | K38: =_xlfn.CONCAT("T Bell-",(LEFT(B38,15)),"-",E38) -> T Bell-THE CITY OVAL H-Ballarat Sales Conference - Food / Amenities | L38: I | M38: =IF(C38>0,C38,-D38) -> 25.07 | N38: T | R38: =LEN(K38) -> 67
A39: 45884 | B39: UBER *TRIP HELP.UBER.C 14518236738 AUS | C39: 33.67 | E39: Ballarat Sales Conference - Uber | F39: G077 | G39: SALP | J39: =IF(F39>0,(_xlfn.CONCAT(F39,".",G39)),H39) -> G077.SALP | K39: =_xlfn.CONCAT("T Bell-",(LEFT(B39,15)),"-",E39) -> T Bell-UBER *TRIP HELP-Ballarat Sales Conference - Uber | L39: I | M39: =IF(C39>0,C39,-D39) -> 33.67 | N39: T | R39: =LEN(K39) -> 55
A40: 45879 | B40: UBER *TRIP HELP.UBER.C 14518236738 AUS | C40: 38 | E40: Ballarat Sales Conference - Uber | F40: G068 | G40: SALP | J40: =IF(F40>0,(_xlfn.CONCAT(F40,".",G40)),H40) -> G068.SALP | K40: =_xlfn.CONCAT("T Bell-",(LEFT(B40,15)),"-",E40) -> T Bell-UBER *TRIP HELP-Ballarat Sales Conference - Uber | L40: I | M40: =IF(C40>0,C40,-D40) -> 38 | N40: T | R40: =LEN(K40) -> 55
... A55: 45879 | B55: ZLR*M1FLATC Melbourne A AUS | C55: 22.9 | E55: Ballarat Sales Conference - Food / Amenities | F55: G068 | G55: SALP | J55: =IF(F55>0,(_xlfn.CONCAT(F55,".",G55)),H55) -> G068.SALP | K55: =_xlfn.CONCAT("T Bell-",(LEFT(B55,15)),"-",E55) -> T Bell-ZLR*M1FLATC Mel-Ballarat Sales Conference - Food / Amenities | L55: I | M55: =IF(C55>0,C55,-D55) -> 22.9 | N55: T | R55: =LEN(K55) -> 67

Sheet S Baker
A1: Employee to code & narrate | J1: To be copied in to pronto
J2: Credit card Statement TOTAL | K2: 98.96
J3: Subtotal | K3: =SUM(M9:M144) -> 98.96
A4: Scott Baker | J4: Variance Check | K4: =K2-K3 -> 0
A5: Reference | B5: =CONCATENATE(Header!$E$4,"BAKER") -> MC-250816BAKER | J5: EMPLOYEES DO NOT CHANGE
A6: Document Date | B6: =Header!$E$5 -> 45885 | E6: Credit card holder to add details
A8: Date | B8: Narrative | C8: Debit Amount | D8: Credit Amount | E8: Description | F8: Project No | G8: Cost Category | H8: GL account | J8: Account | K8: Reference | L8: Tax | M8: Amount | N8: Tax CODE | O8: TAX Amount (leave blank) | P8: CBS - Only if required | R8: limit 56charaters
A9: 45862 | B9: BUNNINGS 329000 DELACOMBE AUS | C9: 98.96 | E9: Delivery team tools - fire blanket | F9: 1073 | G9: TOOL | J9: =IF(F9>0,(_xlfn.CONCAT(F9,".",G9)),H9) -> 1073.TOOL | K9: =_xlfn.CONCAT("S Baker-",(LEFT(B9,15)),"-",E9) -> S Baker-BUNNINGS 329000-Delivery team tools - fire blanket | L9: I | M9: =IF(C9>0,C9,-D9) -> 98.96 | N9: T | Q9: CBS - needs to be pasted seperately | R9: =LEN(K9) -> 58
R10: =LEN(K10) -> 0
R11: =LEN(K11) -> 0
R12: =LEN(K12) -> 0
R13: =LEN(K13) -> 0
R14: =LEN(K14) -> 0
R15: =LEN(K15) -> 0
R16: =LEN(K16) -> 0
R17: =LEN(K17) -> 0
R18: =LEN(K18) -> 0
R19: =LEN(K19) -> 0
R20: =LEN(K20) -> 0
R21: =LEN(K21) -> 0
... R35: =LEN(K35) -> 0

Sheet S Barclay
A1: Employee to code & narrate | J1: To be copied in to pronto
J2: Credit card Statement TOTAL | K2: 532.97
J3: Subtotal | K3: =SUM(M9:M144) -> 532.97
A4: Simon Barclay | J4: Variance Check | K4: =K2-K3 -> 0
A5: Reference | B5: =CONCATENATE(Header!$E$4,"Barclay") -> MC-250816Barclay | J5: EMPLOYEES DO NOT CHANGE
A6: Document Date | B6: =Header!$E$5 -> 45885 | E6: Credit card holder to add details
A8: Date | B8: Narrative | C8: Debit Amount | D8: Credit Amount | E8: Description | F8: Project No | G8: Cost Category | H8: GL account | J8: Account | K8: Reference | L8: Tax | M8: Amount | N8: Tax CODE | O8: TAX Amount (leave blank) | P8: CBS - Only if required | R8: limit 56charaters
A9: 45884 | B9: WOOLWORTHS 3066 ALFREDTON AUS | C9: 216.27 | E9: Pantry supplies | F9: 1084 | G9: STAF | J9: =IF(F9>0,(_xlfn.CONCAT(F9,".",G9)),H9) -> 1084.STAF | K9: =_xlfn.CONCAT("S Barclay-",(LEFT(B9,15)),"-",E9) -> S Barclay-WOOLWORTHS -Pantry supplies | L9: I | M9: =IF(C9>0,C9,-D9) -> 216.27 | N9: T | Q9: CBS - needs to be pasted seperately | R9: =LEN(K9) -> 41
A10: 45876 | B10: WOOLWORTHS 3066 ALFREDTON AUS | C10: 93.93 | E10: Pantry Supplies | F10: 1084 | G10: STAF | J10: =IF(F10>0,(_xlfn.CONCAT(F10,".",G10)),H10) -> 1084.STAF | K10: =_xlfn.CONCAT("S Barclay-",(LEFT(B10,15)),"-",E10) -> S Barclay-WOOLWORTHS -Pantry Supplies | L10: I | M10: =IF(C10>0,C10,-D10) -> 93.93 | N10: T | R10: =LEN(K10) -> 41
A11: 45871 | B11: LINKT MELBOURNE MELBOURNE AUS | C11: 33.92 | E11: Toll | F11: 1073 | G11: MVPT | J11: =IF(F11>0,(_xlfn.CONCAT(F11,".",G11)),H11) -> 1073.MVPT | K11: =_xlfn.CONCAT("S Barclay-",(LEFT(B11,15)),"-",E11) -> S Barclay-LINKT MELBOURNE-Toll | L11: I | M11: =IF(C11>0,C11,-D11) -> 33.92 | N11: T | R11: =LEN(K11) -> 30
A12: 45869 | B12: OFFICEWORKS 0364OFFICE BALLARAT AUS | C12: 58 | E12: Stationary | F12: 1084 | G12: STAT | J12: =IF(F12>0,(_xlfn.CONCAT(F12,".",G12)),H12) -> 1084.STAT | K12: =_xlfn.CONCAT("S Barclay-",(LEFT(B12,15)),"-",E12) -> S Barclay-OFFICEWORKS 036-Stationary | L12: I | M12: =IF(C12>0,C12,-D12) -> 58 | N12: T | R12: =LEN(K12) -> 36
A13: 45868 | B13: J AND M CATERING SERVI WENDOUREE AUS | C13: 77.5 | E13: Stocktake catering | F13: 1077 | G13: ENON | J13: =IF(F13>0,(_xlfn.CONCAT(F13,".",G13)),H13) -> 1077.ENON | K13: =_xlfn.CONCAT("S Barclay-",(LEFT(B13,15)),"-",E13) -> S Barclay-J AND M CATERIN-Stocktake catering | L13: I | M13: =IF(C13>0,C13,-D13) -> 77.5 | N13: T | R13: =LEN(K13) -> 44
A14: 45866 | B14: BUNNINGS 329000 DELACOMBE AUS | C14: 53.35 | F14: 1073 | G14: TOOL | J14: =IF(F14>0,(_xlfn.CONCAT(F14,".",G14)),H14) -> 1073.TOOL | K14: =_xlfn.CONCAT("S Barclay-",(LEFT(B14,15)),"-",E14) -> S Barclay-BUNNINGS 329000- | L14: I | M14: =IF(C14>0,C14,-D14) -> 53.35 | N14: T | R14: =LEN(K14) -> 26
R15: =LEN(K15) -> 0
R16: =LEN(K16) -> 0
R17: =LEN(K17) -> 0
R18: =LEN(K18) -> 0
R19: =LEN(K19) -> 0
R20: =LEN(K20) -> 0
R21: =LEN(K21) -> 0
R22: =LEN(K22) -> 0
R23: =LEN(K23) -> 0
R24: =LEN(K24) -> 0
R25: =LEN(K25) -> 0
R26: =LEN(K26) -> 0
... R35: =LEN(K35) -> 0

Sheet M Brown
A1: Employee to code & narrate | J1: To be copied in to pronto
J2: Credit card Statement TOTAL | K2: 2525.33
J3: Subtotal | K3: =SUM(M9:M144) -> 2525.33
A4: Michael Brown | J4: Variance Check | K4: =K2-K3 -> 0
A5: Reference | B5: =CONCATENATE(Header!$E$4,"Brown") -> MC-250816Brown | J5: EMPLOYEES DO NOT CHANGE
A6: Document Date | B6: =Header!$E$5 -> 45885 | E6: Credit card holder to add details
A8: Date | B8: Narrative | C8: Debit Amount | D8: Credit Amount | E8: Description | F8: Project No | G8: Cost Category | H8: GL account | J8: Account | K8: Reference | L8: Tax | M8: Amount | N8: Tax CODE | O8: TAX Amount (leave blank) | P8: CBS - Only if required | R8: limit 56charaters
A9: 45881 | B9: BUNNINGS 329000 DELACOMBE AUS | C9: 44.94 | E9: Powerboards | F9: 1084 | G9: repm | J9: =IF(F9>0,(_xlfn.CONCAT(F9,".",G9)),H9) -> 1084.repm | K9: =_xlfn.CONCAT("M Brown-",(LEFT(B9,15)),"-",E9) -> M Brown-BUNNINGS 329000-Powerboards | L9: I | M9: =IF(C9>0,C9,-D9) -> 44.94 | N9: T | Q9: CBS - needs to be pasted seperately | R9: =LEN(K9) -> 35
A10: 45881 | B10: BALLARAT SAFETY PTY L BALLARAT AUS | C10: 17.6 | E10: Safety boot insole | F10: 1084 | G10: sppe | J10: =IF(F10>0,(_xlfn.CONCAT(F10,".",G10)),H10) -> 1084.sppe | K10: =_xlfn.CONCAT("M Brown-",(LEFT(B10,15)),"-",E10) -> M Brown-BALLARAT SAFETY-Safety boot insole | L10: I | M10: =IF(C10>0,C10,-D10) -> 17.6 | N10: T | R10: =LEN(K10) -> 42
A11: 45881 | B11: Industrial World BALLARAT AUS | C11: 25.61 | E11: PV5 drive belts | F11: 1051g | G11: repm | J11: =IF(F11>0,(_xlfn.CONCAT(F11,".",G11)),H11) -> 1051g.repm | K11: =_xlfn.CONCAT("M Brown-",(LEFT(B11,15)),"-",E11) -> M Brown-Industrial Worl-PV5 drive belts | L11: I | M11: =IF(C11>0,C11,-D11) -> 25.61 | N11: T | R11: =LEN(K11) -> 39
A12: 45877 | B12: TOTAL TOOLS BALLARAT BALLARAT AUS | C12: 114.2 | E12: Gas burner for weed removal | F12: 1084 | G12: repm | J12: =IF(F12>0,(_xlfn.CONCAT(F12,".",G12)),H12) -> 1084.repm | K12: =_xlfn.CONCAT("M Brown-",(LEFT(B12,15)),"-",E12) -> M Brown-TOTAL TOOLS BAL-Gas burner for weed removal | L12: I | M12: =IF(C12>0,C12,-D12) -> 114.2 | N12: T | R12: =LEN(K12) -> 51
A13: 45876 | B13: STARLINK INTERNET Sydney AUS | C13: 139 | E13: Mt Coghill inernet | F13: 1084 | G13: inte | J13: =IF(F13>0,(_xlfn.CONCAT(F13,".",G13)),H13) -> 1084.inte | K13: =_xlfn.CONCAT("M Brown-",(LEFT(B13,15)),"-",E13) -> M Brown-STARLINK INTERN-Mt Coghill inernet | L13: I | M13: =IF(C13>0,C13,-D13) -> 139 | N13: T | R13: =LEN(K13) -> 42
A14: 45875 | B14: BUNNINGS 329000 DELACOMBE AUS | C14: 44.7 | E14: 15 amp Switch lead | F14: 1084 | G14: repm | J14: =IF(F14>0,(_xlfn.CONCAT(F14,".",G14)),H14) -> 1084.repm | K14: =_xlfn.CONCAT("M Brown-",(LEFT(B14,15)),"-",E14) -> M Brown-BUNNINGS 329000-15 amp Switch lead | L14: I | M14: =IF(C14>0,C14,-D14) -> 44.7 | N14: T | R14: =LEN(K14) -> 42
A15: 45875 | B15: UNITED BALLARAT EURE WENDOUREE AUS | C15: 122.62 | E15: Ute fuel | F15: 1084 | G15: mvpf | J15: =IF(F15>0,(_xlfn.CONCAT(F15,".",G15)),H15) -> 1084.mvpf | K15: =_xlfn.CONCAT("M Brown-",(LEFT(B15,15)),"-",E15) -> M Brown-UNITED BALLARAT-Ute fuel | L15: I | M15: =IF(C15>0,C15,-D15) -> 122.62 | N15: T | R15: =LEN(K15) -> 32
A16: 45874 | B16: AWM WENDOUREE WENDOUREE AUS | C16: 184.67 | E16: B1 airconditioners | F16: 1084 | G16: repm | J16: =IF(F16>0,(_xlfn.CONCAT(F16,".",G16)),H16) -> 1084.repm | K16: =_xlfn.CONCAT("M Brown-",(LEFT(B16,15)),"-",E16) -> M Brown-AWM WENDOUREE W-B1 airconditioners | L16: I | M16: =IF(C16>0,C16,-D16) -> 184.67 | N16: T | R16: =LEN(K16) -> 42
A17: 45874 | B17: CRED VOUCHER AWM WENDOUREE WENDOUREE AUS | D17: 71.98 | E17: Overcharge credit | F17: 1084 | G17: repm | J17: =IF(F17>0,(_xlfn.CONCAT(F17,".",G17)),H17) -> 1084.repm | K17: =_xlfn.CONCAT("M Brown-",(LEFT(B17,15)),"-",E17) -> M Brown-CRED VOUCHER AW-Overcharge credit | L17: I | M17: =IF(C17>0,C17,-D17) -> -71.98 | N17: T | R17: =LEN(K17) -> 41
A18: 45874 | B18: L&H WENDOUREE WENDOUREE AUS | C18: 241.66 | E18: B1 airconditioners | F18: 1084 | G18: repm | J18: =IF(F18>0,(_xlfn.CONCAT(F18,".",G18)),H18) -> 1084.repm | K18: =_xlfn.CONCAT("M Brown-",(LEFT(B18,15)),"-",E18) -> M Brown-L&H WENDOUREE W-B1 airconditioners | L18: I | M18: =IF(C18>0,C18,-D18) -> 241.66 | N18: T | R18: =LEN(K18) -> 42
A19: 45869 | B19: Ballarat Materials Ha MITCHELL PA AUS | C19: 250.97 | E19: Pallet rack load limit signs | F19: 1084 | G19: sppe | J19: =IF(F19>0,(_xlfn.CONCAT(F19,".",G19)),H19) -> 1084.sppe | K19: =_xlfn.CONCAT("M Brown-",(LEFT(B19,15)),"-",E19) -> M Brown-Ballarat Materi-Pallet rack load limit signs | L19: I | M19: =IF(C19>0,C19,-D19) -> 250.97 | N19: T | R19: =LEN(K19) -> 52
A20: 45868 | B20: AVENUTUM BALLARAT BALLARAT AUS | C20: 486.57 | E20: PV5 safety switck | F20: 1051g | G20: repm | J20: =IF(F20>0,(_xlfn.CONCAT(F20,".",G20)),H20) -> 1051g.repm | K20: =_xlfn.CONCAT("M Brown-",(LEFT(B20,15)),"-",E20) -> M Brown-AVENUTUM BALLAR-PV5 safety switck | L20: I | M20: =IF(C20>0,C20,-D20) -> 486.57 | N20: T | R20: =LEN(K20) -> 41
A21: 45868 | B21: UNITED BALLARAT EURE WENDOUREE AUS | C21: 118.34 | E21: Ute fuel | F21: 1084 | G21: mvpf | J21: =IF(F21>0,(_xlfn.CONCAT(F21,".",G21)),H21) -> 1084.mvpf | K21: =_xlfn.CONCAT("M Brown-",(LEFT(B21,15)),"-",E21) -> M Brown-UNITED BALLARAT-Ute fuel | L21: I | M21: =IF(C21>0,C21,-D21) -> 118.34 | N21: T | R21: =LEN(K21) -> 32
A22: 45866 | B22: Ballarat Bolts & Fast DELACOMBE AUS | C22: 4.06 | E22: PV5 bolts | F22: 1051g | G22: repm | J22: =IF(F22>0,(_xlfn.CONCAT(F22,".",G22)),H22) -> 1051g.repm | K22: =_xlfn.CONCAT("M Brown-",(LEFT(B22,15)),"-",E22) -> M Brown-Ballarat Bolts -PV5 bolts | L22: I | M22: =IF(C22>0,C22,-D22) -> 4.06 | N22: T | R22: =LEN(K22) -> 33
A23: 45863 | B23: BUNNINGS 329000 DELACOMBE AUS | C23: 33 | E23: Coach bolts | F23: 1084 | G23: repm | J23: =IF(F23>0,(_xlfn.CONCAT(F23,".",G23)),H23) -> 1084.repm | K23: =_xlfn.CONCAT("M Brown-",(LEFT(B23,15)),"-",E23) -> M Brown-BUNNINGS 329000-Coach bolts | L23: I | M23: =IF(C23>0,C23,-D23) -> 33 | N23: T | R23: =LEN(K23) -> 35
A24: 45860 | B24: STERIDIUM PTY LTD CLEAR ISLAN AUS | C24: 483.87 | E24: Assay oven controler | F24: 1051g | G24: repm | J24: =IF(F24>0,(_xlfn.CONCAT(F24,".",G24)),H24) -> 1051g.repm | K24: =_xlfn.CONCAT("M Brown-",(LEFT(B24,15)),"-",E24) -> M Brown-STERIDIUM PTY L-Assay oven controler | L24: I | M24: =IF(C24>0,C24,-D24) -> 483.87 | N24: T | R24: =LEN(K24) -> 44
A25: 45859 | B25: BUNNINGS 329000 DELACOMBE AUS | C25: 59.45 | E25: LM5 cables | F25: 1051g | G25: repm | J25: =IF(F25>0,(_xlfn.CONCAT(F25,".",G25)),H25) -> 1051g.repm | K25: =_xlfn.CONCAT("M Brown-",(LEFT(B25,15)),"-",E25) -> M Brown-BUNNINGS 329000-LM5 cables | L25: I | M25: =IF(C25>0,C25,-D25) -> 59.45 | N25: T | R25: =LEN(K25) -> 34
A26: 45859 | B26: UNITED BALLARAT EURE WENDOUREE AUS | C26: 118.45 | E26: Ute fuel | F26: 1084 | G26: mvpf | J26: =IF(F26>0,(_xlfn.CONCAT(F26,".",G26)),H26) -> 1084.mvpf | K26: =_xlfn.CONCAT("M Brown-",(LEFT(B26,15)),"-",E26) -> M Brown-UNITED BALLARAT-Ute fuel | L26: I | M26: =IF(C26>0,C26,-D26) -> 118.45 | N26: T | R26: =LEN(K26) -> 32
A27: 45856 | B27: L&H WENDOUREE WENDOUREE AUS | C27: 73.61 | E27: Assay oven fan motors | F27: 1051g | G27: repm | J27: =IF(F27>0,(_xlfn.CONCAT(F27,".",G27)),H27) -> 1051g.repm | K27: =_xlfn.CONCAT("M Brown-",(LEFT(B27,15)),"-",E27) -> M Brown-L&H WENDOUREE W-Assay oven fan motors | L27: I | M27: =IF(C27>0,C27,-D27) -> 73.61 | N27: T | R27: =LEN(K27) -> 45
A28: 45855 | B28: COLES 0628COLES 0628 BALLARAT AUS | C28: 12 | E28: B2 kitchen supplies | F28: 1084 | G28: repm | J28: =IF(F28>0,(_xlfn.CONCAT(F28,".",G28)),H28) -> 1084.repm | K28: =_xlfn.CONCAT("M Brown-",(LEFT(B28,15)),"-",E28) -> M Brown-COLES 0628COLES-B2 kitchen supplies | L28: I | M28: =IF(C28>0,C28,-D28) -> 12 | N28: T | R28: =LEN(K28) -> 43
A29: 45854 | B29: BUNNINGS 329000 DELACOMBE AUS | C29: 21.99 | E29: B2 rubbish bin | F29: 1084 | G29: repm | J29: =IF(F29>0,(_xlfn.CONCAT(F29,".",G29)),H29) -> 1084.repm | K29: =_xlfn.CONCAT("M Brown-",(LEFT(B29,15)),"-",E29) -> M Brown-BUNNINGS 329000-B2 rubbish bin | L29: I | M29: =IF(C29>0,C29,-D29) -> 21.99 | N29: T | R29: =LEN(K29) -> 38
R30: =LEN(K30) -> 0
R31: =LEN(K31) -> 0
R32: =LEN(K32) -> 0
R33: =LEN(K33) -> 0
R34: =LEN(K34) -> 0
R35: =LEN(K35) -> 0

Sheet M Donadio
A1: Employee to code & narrate | J1: To be copied in to pronto
J2: Credit card Statement TOTAL | K2: 5018.74
J3: Subtotal | K3: =SUM(M9:M144) -> 5018.74
A4: Mark Donadio | J4: Variance Check | K4: =K2-K3 -> 0
A5: Reference | B5: =CONCATENATE(Header!$E$4,"Donadio") -> MC-250816Donadio | J5: EMPLOYEES DO NOT CHANGE
A6: Document Date | B6: =Header!$E$5 -> 45885 | E6: Credit card holder to add details
A8: Date | B8: Narrative | C8: Debit Amount | D8: Credit Amount | E8: Description | F8: Project No | G8: Cost Category | H8: GL account | J8: Account | K8: Reference | L8: Tax | M8: Amount | N8: Tax CODE | O8: TAX Amount (leave blank) | P8: CBS - Only if required | R8: limit 56charaters
A9: 45881 | B9: SP XNOTE DOVER USA | C9: 1135.57 | E9: trial of Ai writing tools x 3 | F9: 1084 | G9: ITHA | J9: =IF(F9>0,(_xlfn.CONCAT(F9,".",G9)),H9) -> 1084.ITHA | K9: =_xlfn.CONCAT("M Donadio-",(LEFT(B9,15)),"-",E9) -> M Donadio-SP XNOTE DOVER -trial of Ai writing tools x 3 | L9: I | M9: =IF(C9>0,C9,-D9) -> 1135.57 | N9: T | Q9: CBS - needs to be pasted seperately | R9: =LEN(K9) -> 55
A10: 45879 | B10: SP RED DRAGON NUTRIT WOONONA AUS | C10: 169.95 | E10: Personal Exp | F10: 1084 | G10: PERS | J10: =IF(F10>0,(_xlfn.CONCAT(F10,".",G10)),H10) -> 1084.PERS | K10: =_xlfn.CONCAT("M Donadio-",(LEFT(B10,15)),"-",E10) -> M Donadio-SP RED DRAGON N-Personal Exp | L10: I | M10: =IF(C10>0,C10,-D10) -> 169.95 | N10: F | R10: =LEN(K10) -> 38
A11: 45877 | B11: CRUST - BALLARAT ROBINA AUS | C11: 963 | E11: Wednesday lunch | F11: 1084 | G11: ENON | J11: =IF(F11>0,(_xlfn.CONCAT(F11,".",G11)),H11) -> 1084.ENON | K11: =_xlfn.CONCAT("M Donadio-",(LEFT(B11,15)),"-",E11) -> M Donadio-CRUST - BALLARA-Wednesday lunch | L11: I | M11: =IF(C11>0,C11,-D11) -> 963 | N11: T | R11: =LEN(K11) -> 41
A12: 45875 | B12: SP RUNAWAYTHELABEL.COM MARRICKVILL AUS | C12: 353.6 | E12: Personal Exp | F12: 1084 | G12: PERS | J12: =IF(F12>0,(_xlfn.CONCAT(F12,".",G12)),H12) -> 1084.PERS | K12: =_xlfn.CONCAT("M Donadio-",(LEFT(B12,15)),"-",E12) -> M Donadio-SP RUNAWAYTHELA-Personal Exp | L12: I | M12: =IF(C12>0,C12,-D12) -> 353.6 | N12: F | R12: =LEN(K12) -> 38
A13: 45873 | B13: DNH*GODADDY#3840902371 SYDNEY AUS | C13: 111.31 | E13: Domain registrations | F13: 1084 | G13: WEBS | J13: =IF(F13>0,(_xlfn.CONCAT(F13,".",G13)),H13) -> 1084.WEBS | K13: =_xlfn.CONCAT("M Donadio-",(LEFT(B13,15)),"-",E13) -> M Donadio-DNH*GODADDY#384-Domain registrations | L13: I | M13: =IF(C13>0,C13,-D13) -> 111.31 | N13: T | R13: =LEN(K13) -> 46
A14: 45871 | B14: CRUST - BALLARAT ROBINA AUS | C14: 137 | E14: Lunch on Go Live weekend | F14: 1084 | G14: ENON | J14: =IF(F14>0,(_xlfn.CONCAT(F14,".",G14)),H14) -> 1084.ENON | K14: =_xlfn.CONCAT("M Donadio-",(LEFT(B14,15)),"-",E14) -> M Donadio-CRUST - BALLARA-Lunch on Go Live weekend | L14: I | M14: =IF(C14>0,C14,-D14) -> 137 | N14: T | R14: =LEN(K14) -> 50
A15: 45868 | B15: SQ *NAOMI & I Soldiers Hi AUS | C15: 54.86 | E15: Morning tea | F15: 1084 | G15: ENON | J15: =IF(F15>0,(_xlfn.CONCAT(F15,".",G15)),H15) -> 1084.ENON | K15: =_xlfn.CONCAT("M Donadio-",(LEFT(B15,15)),"-",E15) -> M Donadio-SQ *NAOMI & I S-Morning tea | L15: I | M15: =IF(C15>0,C15,-D15) -> 54.86 | N15: T | R15: =LEN(K15) -> 37
A16: 45868 | B16: BWS LIQUOR 3834 WENDOUREE AUS | C16: 78 | E16: Gift for Daniel V (Staff costs and Amenities) | F16: 1084 | G16: STAF | J16: =IF(F16>0,(_xlfn.CONCAT(F16,".",G16)),H16) -> 1084.STAF | K16: =_xlfn.CONCAT("M Donadio-",(LEFT(B16,15)),"-",E16) -> M Donadio-BWS LIQUOR -Gift for Daniel V (Staff costs and Amenities) | L16: I | M16: =IF(C16>0,C16,-D16) -> 78 | N16: T | R16: =LEN(K16) -> 71
A17: 45868 | B17: WOOLWORTHS 3309 WENDOUREE AUS | C17: 77.5 | E17: Morning tea | F17: 1084 | G17: ENON | J17: =IF(F17>0,(_xlfn.CONCAT(F17,".",G17)),H17) -> 1084.ENON | K17: =_xlfn.CONCAT("M Donadio-",(LEFT(B17,15)),"-",E17) -> M Donadio-WOOLWORTHS -Morning tea | L17: I | M17: =IF(C17>0,C17,-D17) -> 77.5 | N17: T | R17: =LEN(K17) -> 37
A18: 45868 | B18: BAKERS DELIGHT WENDOUR WENDOUREE AUS | C18: 52.1 | E18: Morning tea | F18: 1084 | G18: ENON | J18: =IF(F18>0,(_xlfn.CONCAT(F18,".",G18)),H18) -> 1084.ENON | K18: =_xlfn.CONCAT("M Donadio-",(LEFT(B18,15)),"-",E18) -> M Donadio-BAKERS DELIGHT -Morning tea | L18: I | M18: =IF(C18>0,C18,-D18) -> 52.1 | N18: T | R18: =LEN(K18) -> 37
A19: 45867 | B19: LinkedIn 10459237796 NORTH SYDNE AUS | C19: 1308.54 | E19: LinkedIn Recruiter | F19: 1084 | G19: RECR | J19: =IF(F19>0,(_xlfn.CONCAT(F19,".",G19)),H19) -> 1084.RECR | K19: =_xlfn.CONCAT("M Donadio-",(LEFT(B19,15)),"-",E19) -> M Donadio-LinkedIn 104592-LinkedIn Recruiter | L19: I | M19: =IF(C19>0,C19,-D19) -> 1308.54 | N19: T | R19: =LEN(K19) -> 44
A20: 45860 | B20: STARLINK INTERNET Sydney AUS | C20: 278 | E20: Internet | F20: 1084 | G20: INTE | J20: =IF(F20>0,(_xlfn.CONCAT(F20,".",G20)),H20) -> 1084.INTE | K20: =_xlfn.CONCAT("M Donadio-",(LEFT(B20,15)),"-",E20) -> M Donadio-STARLINK INTERN-Internet | L20: I | M20: =IF(C20>0,C20,-D20) -> 278 | N20: T | R20: =LEN(K20) -> 34
A21: 45860 | B21: WOOLWORTHS 3309 WENDOUREE AUS | C21: 89.48 | E21: Morning tea | F21: 1084 | G21: ENON | J21: =IF(F21>0,(_xlfn.CONCAT(F21,".",G21)),H21) -> 1084.ENON | K21: =_xlfn.CONCAT("M Donadio-",(LEFT(B21,15)),"-",E21) -> M Donadio-WOOLWORTHS -Morning tea | L21: I | M21: =IF(C21>0,C21,-D21) -> 89.48 | N21: T | R21: =LEN(K21) -> 37
... A25: 45854 | B25: WOOLWORTHS 3309 WENDOUREE AUS | C25: 27 | E25: Morning tea | F25: 1084 | G25: ENON | J25: =IF(F25>0,(_xlfn.CONCAT(F25,".",G25)),H25) -> 1084.ENON | K25: =_xlfn.CONCAT("M Donadio-",(LEFT(B25,15)),"-",E25) -> M Donadio-WOOLWORTHS -Morning tea | L25: I | M25: =IF(C25>0,C25,-D25) -> 27 | N25: T | R25: =LEN(K25) -> 37
A26: 45853 | B26: DNH*GODADDY#3840902371 SYDNEY AUS | C26: 70.2 | E26: Domain registrations | F26: 1084 | G26: WEBS | J26: =IF(F26>0,(_xlfn.CONCAT(F26,".",G26)),H26) -> 1084.WEBS | K26: =_xlfn.CONCAT("M Donadio-",(LEFT(B26,15)),"-",E26) -> M Donadio-DNH*GODADDY#384-Domain registrations | M26: =IF(C26>0,C26,-D26) -> 70.2 | N26: T | R26: =LEN(K26) -> 46
R27: =LEN(K27) -> 0
R28: =LEN(K28) -> 0
R29: =LEN(K29) -> 0
R30: =LEN(K30) -> 0
R31: =LEN(K31) -> 0
R32: =LEN(K32) -> 0
R33: =LEN(K33) -> 0
R34: =LEN(K34) -> 0
R35: =LEN(K35) -> 0

Sheet L DUva
A1: Employee to code & narrate | J1: To be copied in to pronto
J2: Credit card Statement TOTAL | K2: 366.53
J3: Subtotal | K3: =SUM(M9:M144) -> 366.53
A4: Lisa Duva | J4: Variance Check | K4: =K2-K3 -> 0
A5: Reference | B5: =CONCATENATE(Header!$E$4,"DUVA") -> MC-250816DUVA | J5: EMPLOYEES DO NOT CHANGE
A6: Document Date | B6: =Header!$E$5 -> 45885 | E6: Credit card holder to add details
A8: Date | B8: Narrative | C8: Debit Amount | D8: Credit Amount | E8: Description | F8: Project No | G8: Cost Category | H8: GL account | J8: Account | K8: Reference | L8: Tax | M8: Amount | N8: Tax CODE | O8: TAX Amount (leave blank) | P8: CBS - Only if required | R8: limit 56charaters
A9: 45881 | B9: SQ *NOURISH KITCHEN & Leederville AUS | C9: 16.9 | E9: Weekly work lunch | F9: 1041 | G9: ENON | J9: =IF(F9>0,(_xlfn.CONCAT(F9,".",G9)),H9) -> 1041.ENON | K9: =_xlfn.CONCAT("L Duva-",(LEFT(B9,15)),"-",E9) -> L Duva-SQ *NOURISH KIT-Weekly work lunch | L9: I | M9: =IF(C9>0,C9,-D9) -> 16.9 | N9: T | Q9: CBS - needs to be pasted seperately | R9: =LEN(K9) -> 40
A10: 45873 | B10: TSUKE BA LEEDERVILLE AUS | C10: 32.5 | E10: Weekly work lunch | F10: 1041 | G10: ENON | J10: =IF(F10>0,(_xlfn.CONCAT(F10,".",G10)),H10) -> 1041.ENON | K10: =_xlfn.CONCAT("L Duva-",(LEFT(B10,15)),"-",E10) -> L Duva-TSUKE BA LEEDER-Weekly work lunch | L10: I | M10: =IF(C10>0,C10,-D10) -> 32.5 | N10: T | R10: =LEN(K10) -> 40
A11: 45871 | B11: UBER *TRIP HELP.UBER.C 14518236738 AUS | C11: 34.98 | E11: Travel - Networking Event: Jeans for Genes fundraiser | F11: 1041 | G11: TRAV | J11: =IF(F11>0,(_xlfn.CONCAT(F11,".",G11)),H11) -> 1041.TRAV | K11: =_xlfn.CONCAT("L Duva-",(LEFT(B11,15)),"-",E11) -> L Duva-UBER *TRIP HELP-Travel - Networking Event: Jeans for Genes fundraiser | L11: I | M11: =IF(C11>0,C11,-D11) -> 34.98 | N11: T | R11: =LEN(K11) -> 76
A12: 45871 | B12: UBER *TRIP HELP.UBER.C 14518236738 AUS | C12: 36.07 | E12: Travel - Networking Event: Jeans for Genes fundraiser | F12: 1041 | G12: TRAV | J12: =IF(F12>0,(_xlfn.CONCAT(F12,".",G12)),H12) -> 1041.TRAV | K12: =_xlfn.CONCAT("L Duva-",(LEFT(B12,15)),"-",E12) -> L Duva-UBER *TRIP HELP-Travel - Networking Event: Jeans for Genes fundraiser | L12: I | M12: =IF(C12>0,C12,-D12) -> 36.07 | N12: T | R12: =LEN(K12) -> 76
A13: 45867 | B13: GYG Leederville Leederville AUS | C13: 26.8 | E13: Weekly work lunch | F13: 1041 | G13: ENON | J13: =IF(F13>0,(_xlfn.CONCAT(F13,".",G13)),H13) -> 1041.ENON | K13: =_xlfn.CONCAT("L Duva-",(LEFT(B13,15)),"-",E13) -> L Duva-GYG Leederville-Weekly work lunch | L13: I | M13: =IF(C13>0,C13,-D13) -> 26.8 | N13: T | R13: =LEN(K13) -> 40
A14: 45855 | B14: AUZICAB 0478 045 250 SOUTHERN RI AUS | C14: 93.24 | E14: Gruyere - Travel to airport | F14: S17144 | G14: TRVP | J14: =IF(F14>0,(_xlfn.CONCAT(F14,".",G14)),H14) -> S17144.TRVP | K14: =_xlfn.CONCAT("L Duva-",(LEFT(B14,15)),"-",E14) -> L Duva-AUZICAB 0478 04-Gruyere - Travel to airport | L14: I | M14: =IF(C14>0,C14,-D14) -> 93.24 | N14: T | P14: 1.6.01 | R14: =LEN(K14) -> 50
A15: 45854 | B15: COMPASS GOLDRDGRUYERE LAVERTON AUS | C15: 13 | E15: Gruyere - Site Networking Drinks | F15: S17144 | G15: TRVP | J15: =IF(F15>0,(_xlfn.CONCAT(F15,".",G15)),H15) -> S17144.TRVP | K15: =_xlfn.CONCAT("L Duva-",(LEFT(B15,15)),"-",E15) -> L Duva-COMPASS GOLDRDG-Gruyere - Site Networking Drinks | L15: I | M15: =IF(C15>0,C15,-D15) -> 13 | N15: T | P15: 1.6.03 | R15: =LEN(K15) -> 55
A16: 45854 | B16: COMPASS GOLDRDGRUYERE LAVERTON AUS | C16: 18.7 | E16: Gruyere - Site Networking Drinks | F16: S17144 | G16: TRVP | J16: =IF(F16>0,(_xlfn.CONCAT(F16,".",G16)),H16) -> S17144.TRVP | K16: =_xlfn.CONCAT("L Duva-",(LEFT(B16,15)),"-",E16) -> L Duva-COMPASS GOLDRDG-Gruyere - Site Networking Drinks | L16: I | M16: =IF(C16>0,C16,-D16) -> 18.7 | N16: T | P16: 1.6.03 | R16: =LEN(K16) -> 55
A17: 45854 | B17: COMPASS GOLDRDGRUYERE LAVERTON AUS | C17: 17.9 | E17: Gruyere - Site Networking Drinks | F17: S17144 | G17: TRVP | J17: =IF(F17>0,(_xlfn.CONCAT(F17,".",G17)),H17) -> S17144.TRVP | K17: =_xlfn.CONCAT("L Duva-",(LEFT(B17,15)),"-",E17) -> L Duva-COMPASS GOLDRDG-Gruyere - Site Networking Drinks | L17: I | M17: =IF(C17>0,C17,-D17) -> 17.9 | N17: T | P17: 1.6.03 | R17: =LEN(K17) -> 55
A18: 45854 | B18: SWAN TAXIS PTY LTD VICTORIA PA AUS | C18: 76.44 | E18: Gruyere - Travel from airport | F18: S17144 | G18: TRVP | J18: =IF(F18>0,(_xlfn.CONCAT(F18,".",G18)),H18) -> S17144.TRVP | K18: =_xlfn.CONCAT("L Duva-",(LEFT(B18,15)),"-",E18) -> L Duva-SWAN TAXIS PTY -Gruyere - Travel from airport | L18: I | M18: =IF(C18>0,C18,-D18) -> 76.44 | N18: T | P18: 1.6.01 | R18: =LEN(K18) -> 52
R19: =LEN(K19) -> 0
R20: =LEN(K20) -> 0
R21: =LEN(K21) -> 0
R22: =LEN(K22) -> 0
R23: =LEN(K23) -> 0
R24: =LEN(K24) -> 0
R25: =LEN(K25) -> 0
R26: =LEN(K26) -> 0
R27: =LEN(K27) -> 0
R28: =LEN(K28) -> 0
R29: =LEN(K29) -> 0
R30: =LEN(K30) -> 0
... R35: =LEN(K35) -> 0

Sheet A Edmondston
A1: Employee to code & narrate | J1: To be copied in to pronto
J2: Credit card Statement TOTAL | K2: 3357.86
J3: Subtotal | K3: =SUM(M9:M146) -> 3357.86
A4: Andrew Edmondston | J4: Variance Check | K4: =K2-K3 -> 0
A5: Reference | B5: =CONCATENATE(Header!$E$4,"Edmondston") -> MC-250816Edmondston | J5: EMPLOYEES DO NOT CHANGE
A6: Document Date | B6: =Header!$E$5 -> 45885 | E6: Credit card holder to add details
A8: Date | B8: Narrative | C8: Debit Amount | D8: Credit Amount | E8: Description | F8: Project No | G8: Cost Category | H8: GL account | J8: Account | K8: Reference | L8: Tax | M8: Amount | N8: Tax CODE | O8: TAX Amount (leave blank) | P8: CBS - Only if required | R8: limit 56charaters
A9: 45883 | B9: Bakers Delight Ballarat Ci AUS | C9: 28.5 | E9: Catering Sales Conference | F9: G068 | G9: SALP | J9: =IF(F9>0,(_xlfn.CONCAT(F9,".",G9)),H9) -> G068.SALP | K9: =_xlfn.CONCAT("A Edmondston-",(LEFT(B9,15)),"-",E9) -> A Edmondston-Bakers Delight -Catering Sales Conference | L9: I | M9: =IF(C9>0,C9,-D9) -> 28.5 | N9: T | Q9: CBS - needs to be pasted seperately | R9: =LEN(K9) -> 54
A10: 45883 | B10: GOLDEN NUGGET BAKERY Wendouree AUS | C10: 75.62 | E10: Catering Sales Conference | F10: G068 | G10: SALP | J10: =IF(F10>0,(_xlfn.CONCAT(F10,".",G10)),H10) -> G068.SALP | K10: =_xlfn.CONCAT("A Edmondston-",(LEFT(B10,15)),"-",E10) -> A Edmondston-GOLDEN NUGGET B-Catering Sales Conference | L10: I | M10: =IF(C10>0,C10,-D10) -> 75.62 | N10: T | R10: =LEN(K10) -> 54
A11: 45882 | B11: Bakers Delight Ballarat Ci AUS | C11: 27 | E11: Catering Sales Conference | F11: G068 | G11: SALP | J11: =IF(F11>0,(_xlfn.CONCAT(F11,".",G11)),H11) -> G068.SALP | K11: =_xlfn.CONCAT("A Edmondston-",(LEFT(B11,15)),"-",E11) -> A Edmondston-Bakers Delight -Catering Sales Conference | L11: I | M11: =IF(C11>0,C11,-D11) -> 27 | N11: T | R11: =LEN(K11) -> 54
A12: 45881 | B12: RYANS IGA MIDVALE MOUNT CLEAR AUS | C12: 16.39 | E12: Catering Sales Conference | F12: G068 | G12: SALP | J12: =IF(F12>0,(_xlfn.CONCAT(F12,".",G12)),H12) -> G068.SALP | K12: =_xlfn.CONCAT("A Edmondston-",(LEFT(B12,15)),"-",E12) -> A Edmondston-RYANS IGA MIDVA-Catering Sales Conference | L12: I | M12: =IF(C12>0,C12,-D12) -> 16.39 | N12: T | R12: =LEN(K12) -> 54
A13: 45880 | B13: RYANS IGA MIDVALE MOUNT CLEAR AUS | C13: 48.23 | E13: Catering Sales Conference | F13: G068 | G13: SALP | J13: =IF(F13>0,(_xlfn.CONCAT(F13,".",G13)),H13) -> G068.SALP | K13: =_xlfn.CONCAT("A Edmondston-",(LEFT(B13,15)),"-",E13) -> A Edmondston-RYANS IGA MIDVA-Catering Sales Conference | L13: I | M13: =IF(C13>0,C13,-D13) -> 48.23 | N13: T | R13: =LEN(K13) -> 54
A14: 45880 | B14: Subway Wendouree Lake Wendou AUS | C14: 128 | E14: Catering Sales Conference | F14: G068 | G14: SALP | J14: =IF(F14>0,(_xlfn.CONCAT(F14,".",G14)),H14) -> G068.SALP | K14: =_xlfn.CONCAT("A Edmondston-",(LEFT(B14,15)),"-",E14) -> A Edmondston-Subway Wendoure-Catering Sales Conference | L14: I | M14: =IF(C14>0,C14,-D14) -> 128 | N14: T | R14: =LEN(K14) -> 54
A15: 45880 | B15: CITYOVA | C15: =527.9*0.2 -> 105.58 | E15: MealAE,TB,NG,WL,SG,ELG,BW,NZ,SM, AL | F15: G068 | G15: SALP | J15: =IF(F15>0,(_xlfn.CONCAT(F15,".",G15)),H15) -> G068.SALP | K15: =_xlfn.CONCAT("A Edmondston-",(LEFT(B15,15)),"-",E15) -> A Edmondston-CITYOVA-MealAE,TB,NG,WL,SG,ELG,BW,NZ,SM, AL | L15: I | M15: =IF(C15>0,C15,-D15) -> 105.58 | N15: T | R15: =LEN(K15) -> 56
A16: 45880 | B16: CITYOva | C16: =527.9*0.8 -> 422.32 | E16: MealAE,TB,NG,WL,SG,ELG,BW,NZ,SM, AL | F16: 1084 | G16: ENFE | J16: =IF(F16>0,(_xlfn.CONCAT(F16,".",G16)),H16) -> 1084.ENFE | K16: =_xlfn.CONCAT("A Edmondston-",(LEFT(B16,15)),"-",E16) -> A Edmondston-CITYOva-MealAE,TB,NG,WL,SG,ELG,BW,NZ,SM, AL | M16: =IF(C16>0,C16,-D16) -> 422.32 | N16: T | R16: =LEN(K16) -> 56
A17: 45877 | B17: POST WENDOUREE VILLAGE WENDOUREE AUS | C17: 19.65 | E17: Post bank guarantees | F17: 1084 | G17: POST | J17: =IF(F17>0,(_xlfn.CONCAT(F17,".",G17)),H17) -> 1084.POST | K17: =_xlfn.CONCAT("A Edmondston-",(LEFT(B17,15)),"-",E17) -> A Edmondston-POST WENDOUREE -Post bank guarantees | L17: I | M17: =IF(C17>0,C17,-D17) -> 19.65 | N17: T | R17: =LEN(K17) -> 49
A18: 45876 | B18: MYKI BALLARAT RS BAT BALLARAT CE AUS | C18: 30 | E18: Train - Melbourne Mining Club | F18: 1084 | G18: TRAV | J18: =IF(F18>0,(_xlfn.CONCAT(F18,".",G18)),H18) -> 1084.TRAV | K18: =_xlfn.CONCAT("A Edmondston-",(LEFT(B18,10)),"-",E18) -> A Edmondston-MYKI BALLA-Train - Melbourne Mining Club | L18: I | M18: =IF(C18>0,C18,-D18) -> 30 | N18: T | R18: =LEN(K18) -> 53
A19: 45876 | B19: SQ *SHOWTIME EVENT GRO Melbourne AUS | C19: =128.52*0.3 -> 38.556 | E19: Wine for table - Melbourne Mining Club AE, MX, SM | F19: 1084 | G19: ENFE | J19: =IF(F19>0,(_xlfn.CONCAT(F19,".",G19)),H19) -> 1084.ENFE | K19: =_xlfn.CONCAT("A Edmondston-",(LEFT(B19,10)),"-",E19) -> A Edmondston-SQ *SHOWTI-Wine for table - Melbourne Mining Club AE, MX, SM | L19: I | M19: =IF(C19>0,C19,-D19) -> 38.556 | N19: T | R19: =LEN(K19) -> 73
A20: 45876 | B20: SQ *SHOWTIME EVENT GRO Melbourne AUS | C20: =128.52*0.7 -> 89.964 | E20: Wine for table - Melbourne Mining Club 7 - Non employees | F20: 1084 | G20: ENFN | J20: =IF(F20>0,(_xlfn.CONCAT(F20,".",G20)),H20) -> 1084.ENFN | K20: =_xlfn.CONCAT("A Edmondston-",(LEFT(B20,10)),"-",E20) -> A Edmondston-SQ *SHOWTI-Wine for table - Melbourne Mining Club 7 - Non employees | L20: I | M20: =IF(C20>0,C20,-D20) -> 89.964 | N20: T | R20: =LEN(K20) -> 80
A21: 45874 | B21: CA ANZ SYDNEY AUS | C21: 899 | E21: Chartered Accountants Aust & NZ Annual Membership | F21: 1084 | G21: MEMB | J21: =IF(F21>0,(_xlfn.CONCAT(F21,".",G21)),H21) -> 1084.MEMB | K21: =_xlfn.CONCAT("A Edmondston-",(LEFT(B21,10)),"-",E21) -> A Edmondston-CA ANZ SYD-Chartered Accountants Aust & NZ Annual Membership | L21: I | M21: =IF(C21>0,C21,-D21) -> 899 | N21: T | R21: =LEN(K21) -> 73
A22: 45870 | B22: GOLDEN NUGGET BAKERY Wendouree AUS | C22: 41.05 | E22: Food for Pronto Team | F22: 1084 | G22: ENON | J22: =IF(F22>0,(_xlfn.CONCAT(F22,".",G22)),H22) -> 1084.ENON | K22: =_xlfn.CONCAT("A Edmondston-",(LEFT(B22,10)),"-",E22) -> A Edmondston-GOLDEN NUG-Food for Pronto Team | L22: I | M22: =IF(C22>0,C22,-D22) -> 41.05 | N22: T | R22: =LEN(K22) -> 44
A23: 45869 | B23: 2 BLOKES COFFEE ROAST MOUNT HELEN AUS | C23: 370 | E23: Coffee Beans | F23: 1084 | G23: STAF | J23: =IF(F23>0,(_xlfn.CONCAT(F23,".",G23)),H23) -> 1084.STAF | K23: =_xlfn.CONCAT("A Edmondston-",(LEFT(B23,10)),"-",E23) -> A Edmondston-2 BLOKES -Coffee Beans | L23: I | M23: =IF(C23>0,C23,-D23) -> 370 | N23: F | R23: =LEN(K23) -> 36
A24: 45865 | B24: ZLR*Liv Eat Western Jun AUS | C24: 15.11 | E24: Food while in Burnie - Elphinstone Group Function | F24: 1084 | G24: TRAV | J24: =IF(F24>0,(_xlfn.CONCAT(F24,".",G24)),H24) -> 1084.TRAV | K24: =_xlfn.CONCAT("A Edmondston-",(LEFT(B24,10)),"-",E24) -> A Edmondston-ZLR*Liv Ea-Food while in Burnie - Elphinstone Group Function | L24: I | M24: =IF(C24>0,C24,-D24) -> 15.11 | N24: T | R24: =LEN(K24) -> 73
A25: 45864 | B25: THE FORESHORE TASMANIA BURNIE AUS | C25: 9.1 | E25: Food while in Burnie - Elphinstone Group Function | F25: 1084 | G25: TRAV | J25: =IF(F25>0,(_xlfn.CONCAT(F25,".",G25)),H25) -> 1084.TRAV | K25: =_xlfn.CONCAT("A Edmondston-",(LEFT(B25,10)),"-",E25) -> A Edmondston-THE FORESH-Food while in Burnie - Elphinstone Group Function | L25: I | M25: =IF(C25>0,C25,-D25) -> 9.1 | N25: T | R25: =LEN(K25) -> 73
A26: 45864 | B26: BELINDA SHEREE DUDFIEL BURNIE AUS | C26: 28 | E26: Food while in Burnie - Elphinstone Group Function | F26: 1084 | G26: TRAV | J26: =IF(F26>0,(_xlfn.CONCAT(F26,".",G26)),H26) -> 1084.TRAV | K26: =_xlfn.CONCAT("A Edmondston-",(LEFT(B26,10)),"-",E26) -> A Edmondston-BELINDA SH-Food while in Burnie - Elphinstone Group Function | L26: I | M26: =IF(C26>0,C26,-D26) -> 28 | N26: T | R26: =LEN(K26) -> 73
A27: 45864 | B27: One North Terrace Burnie AUS | C27: 604.76 | E27: Accom Burnie - Elphinstone Group Function | F27: 1084 | G27: TRAV | J27: =IF(F27>0,(_xlfn.CONCAT(F27,".",G27)),H27) -> 1084.TRAV | K27: =_xlfn.CONCAT("A Edmondston-",(LEFT(B27,10)),"-",E27) -> A Edmondston-One North -Accom Burnie - Elphinstone Group Function | L27: I | M27: =IF(C27>0,C27,-D27) -> 604.76 | N27: T | R27: =LEN(K27) -> 65
A28: 45864 | B28: Penguin Country Bakeh Penguin AUS | C28: 11.1 | E28: Meals Burnie - Elphinstone Group Function | F28: 1084 | G28: TRAV | J28: =IF(F28>0,(_xlfn.CONCAT(F28,".",G28)),H28) -> 1084.TRAV | K28: =_xlfn.CONCAT("A Edmondston-",(LEFT(B28,10)),"-",E28) -> A Edmondston-Penguin Co-Meals Burnie - Elphinstone Group Function | L28: I | M28: =IF(C28>0,C28,-D28) -> 11.1 | N28: T | R28: =LEN(K28) -> 65
A29: 45863 | B29: SQ *EMBER & VINES Burnie, Tas AUS | C29: 135.5 | E29: MealsBurnie -AE &V De Santis | F29: 1084 | G29: TRAV | J29: =IF(F29>0,(_xlfn.CONCAT(F29,".",G29)),H29) -> 1084.TRAV | K29: =_xlfn.CONCAT("A Edmondston-",(LEFT(B29,10)),"-",E29) -> A Edmondston-SQ *EMBER -MealsBurnie -AE &V De Santis | L29: I | M29: =IF(C29>0,C29,-D29) -> 135.5 | N29: T | R29: =LEN(K29) -> 52
A30: 45863 | B30: BELINDA SHEREE DUDFIEL BURNIE AUS | C30: 15.5 | E30: Food while in Burnie - Elphinstone Group Function | F30: 1084 | G30: TRAV | J30: =IF(F30>0,(_xlfn.CONCAT(F30,".",G30)),H30) -> 1084.TRAV | K30: =_xlfn.CONCAT("A Edmondston-",(LEFT(B30,10)),"-",E30) -> A Edmondston-BELINDA SH-Food while in Burnie - Elphinstone Group Function | L30: I | M30: =IF(C30>0,C30,-D30) -> 15.5 | N30: T | R30: =LEN(K30) -> 73
A31: 45863 | B31: UBER *TRIP HELP.UBER.C 14518236738 AUS | C31: 19.87 | E31: Taxi to station for Burnie trip-Elphinstone Group Function | F31: 1084 | G31: TRAV | J31: =IF(F31>0,(_xlfn.CONCAT(F31,".",G31)),H31) -> 1084.TRAV | K31: =_xlfn.CONCAT("A Edmondston-",(LEFT(B31,10)),"-",E31) -> A Edmondston-UBER *TRIP-Taxi to station for Burnie trip-Elphinstone Group Function | L31: I | M31: =IF(C31>0,C31,-D31) -> 19.87 | N31: T | R31: =LEN(K31) -> 82
A32: 45862 | B32: KFC BURNIE BURNIE AUS | C32: 15.45 | E32: Food while in Burnie - Elphinstone Group Function | F32: 1084 | G32: TRAV | J32: =IF(F32>0,(_xlfn.CONCAT(F32,".",G32)),H32) -> 1084.TRAV | K32: =_xlfn.CONCAT("A Edmondston-",(LEFT(B32,10)),"-",E32) -> A Edmondston-KFC BURNIE-Food while in Burnie - Elphinstone Group Function | L32: I | M32: =IF(C32>0,C32,-D32) -> 15.45 | N32: T | R32: =LEN(K32) -> 73
... A35: 45861 | B35: Airport Shuttle Bus BAKERY HILL AUS | C35: 90 | E35: Shuttle bus - Elphinstone Group Function | F35: 1084 | G35: TRAV | J35: =IF(F35>0,(_xlfn.CONCAT(F35,".",G35)),H35) -> 1084.TRAV | K35: =_xlfn.CONCAT("A Edmondston-",(LEFT(B35,10)),"-",E35) -> A Edmondston-Airport Sh-Shuttle bus - Elphinstone Group Function | L35: I | M35: =IF(C35>0,C35,-D35) -> 90 | N35: T | R35: =LEN(K35) -> 64
R36: =LEN(K36) -> 0
R37: =LEN(K37) -> 0

Sheet M Gort
A1: Employee to code & narrate | J1: To be copied in to pronto
J2: Credit card Statement TOTAL | K2: 622.79
J3: Subtotal | K3: =SUM(M9:M144) -> 622.79
A4: Marleen Gort | J4: Variance Check | K4: =K2-K3 -> 0
A5: Reference | B5: =CONCATENATE(Header!$E$4,"Gort") -> MC-250816Gort | J5: EMPLOYEES DO NOT CHANGE
A6: Document Date | B6: =Header!$E$5 -> 45885 | E6: Credit card holder to add details
A8: Date | B8: Narrative | C8: Debit Amount | D8: Credit Amount | E8: Description | F8: Project No | G8: Cost Category | H8: GL account | J8: Account | K8: Reference | L8: Tax | M8: Amount | N8: Tax CODE | O8: TAX Amount (leave blank) | P8: CBS - Only if required | R8: limit 56charaters
A9: 45867 | B9: Yoast B.V. merchantRef Wijchen NLD FRGN AMT: 267.30 U. S. DOLLAR | C9: 422.72 | E9: Website SEO plugin yearly fee | F9: 1084 | G9: ITSW | J9: =IF(F9>0,(_xlfn.CONCAT(F9,".",G9)),H9) -> 1084.ITSW | K9: =_xlfn.CONCAT("M Gort-",(LEFT(B9,15)),"-",E9) -> M Gort-Yoast B.V. merc-Website SEO plugin yearly fee | L9: I | M9: =IF(C9>0,C9,-D9) -> 422.72 | N9: F | Q9: CBS - needs to be pasted seperately | R9: =LEN(K9) -> 53
A10: 45863 | B10: Adobe Sydney AUS | C10: 96.99 | E10: Adobe Creative Cloud monthly fee | F10: 1084 | G10: ITSW | J10: =IF(F10>0,(_xlfn.CONCAT(F10,".",G10)),H10) -> 1084.ITSW | K10: =_xlfn.CONCAT("M Gort-",(LEFT(B10,15)),"-",E10) -> M Gort-Adobe Sydney AU-Adobe Creative Cloud monthly fee | L10: I | M10: =IF(C10>0,C10,-D10) -> 96.99 | N10: T | R10: =LEN(K10) -> 56
A11: 45856 | B11: CODETWO JELENIA GOR POL FRGN AMT: 64.58 U. S. DOLLAR | C11: 103.08 | E11: Signature software extra licenses | F11: 1060GE2 | G11: MISC | J11: =IF(F11>0,(_xlfn.CONCAT(F11,".",G11)),H11) -> 1060GE2.MISC | K11: =_xlfn.CONCAT("M Gort-",(LEFT(B11,15)),"-",E11) -> M Gort-CODETWO JELENIA-Signature software extra licenses | L11: I | M11: =IF(C11>0,C11,-D11) -> 103.08 | N11: F | R11: =LEN(K11) -> 57
R12: =LEN(K12) -> 0
R13: =LEN(K13) -> 0
R14: =LEN(K14) -> 0
R15: =LEN(K15) -> 0
R16: =LEN(K16) -> 0
R17: =LEN(K17) -> 0
R18: =LEN(K18) -> 0
R19: =LEN(K19) -> 0
R20: =LEN(K20) -> 0
R21: =LEN(K21) -> 0
R22: =LEN(K22) -> 0
R23: =LEN(K23) -> 0
... R35: =LEN(K35) -> 0

Sheet N Grigg
A1: Employee to code & narrate | J1: To be copied in to pronto
J2: Credit card Statement TOTAL | K2: 4667.18
J3: Subtotal | K3: =SUM(M9:M144) -> 4667.18
A4: Nigel Grigg | J4: Variance Check | K4: =K2-K3 -> 0
A5: Reference | B5: =CONCATENATE(Header!$E$4,"Grigg") -> MC-250816Grigg | J5: EMPLOYEES DO NOT CHANGE
A6: Document Date | B6: =Header!$E$5 -> 45885 | E6: Credit card holder to add details
A8: Date | B8: Narrative | C8: Debit Amount | D8: Credit Amount | E8: Description | F8: Project No | G8: Cost Category | H8: GL account | J8: Account | K8: Reference | L8: Tax | M8: Amount | N8: Tax CODE | O8: TAX Amount (leave blank) | P8: CBS - Only if required | R8: limit 56charaters
A9: 45882 | B9: WHSMITH SYD PIERC SAT MASCOT AUS | C9: 10.13 | E9: airport - Drinks | F9: G077 | G9: SALP | J9: =IF(F9>0,(_xlfn.CONCAT(F9,".",G9)),H9) -> G077.SALP | K9: =_xlfn.CONCAT("N Grigg-",(LEFT(B9,15)),"-",E9) -> N Grigg-WHSMITH SYD PIE-airport - Drinks | L9: I | M9: =IF(C9>0,C9,-D9) -> 10.13 | N9: T | Q9: CBS - needs to be pasted seperately | R9: =LEN(K9) -> 40
A10: 45882 | B10: TRANSPORTFORNSW TAP SYDNEY AUS | C10: 8.03 | E10: Travel NC | F10: G077 | G10: SALP | J10: =IF(F10>0,(_xlfn.CONCAT(F10,".",G10)),H10) -> G077.SALP | K10: =_xlfn.CONCAT("N Grigg-",(LEFT(B10,15)),"-",E10) -> N Grigg-TRANSPORTFORNSW-Travel NC | L10: I | M10: =IF(C10>0,C10,-D10) -> 8.03 | N10: T | R10: =LEN(K10) -> 33
A11: 45882 | B11: ZLR*S1TOBYA Mascot AUS | C11: 6.59 | E11: Travel NC | F11: G077 | G11: SALP | J11: =IF(F11>0,(_xlfn.CONCAT(F11,".",G11)),H11) -> G077.SALP | K11: =_xlfn.CONCAT("N Grigg-",(LEFT(B11,15)),"-",E11) -> N Grigg-ZLR*S1TOBYA Mas-Travel NC | L11: I | M11: =IF(C11>0,C11,-D11) -> 6.59 | N11: T | R11: =LEN(K11) -> 33
A12: 45881 | B12: UFS HEALTHCARE LTD BALLARAT AUS | C12: 27.18 | E12: Persoanl Cost | F12: 1084 | G12: PERS | J12: =IF(F12>0,(_xlfn.CONCAT(F12,".",G12)),H12) -> 1084.PERS | K12: =_xlfn.CONCAT("N Grigg-",(LEFT(B12,15)),"-",E12) -> N Grigg-UFS HEALTHCARE -Persoanl Cost | L12: I | M12: =IF(C12>0,C12,-D12) -> 27.18 | N12: F | R12: =LEN(K12) -> 37
A13: 45881 | B13: APCO ALFREDTON ALFREDTON AUS | C13: 112.79 | E13: Travel NC - Fuel - | F13: G077 | G13: SALP | J13: =IF(F13>0,(_xlfn.CONCAT(F13,".",G13)),H13) -> G077.SALP | K13: =_xlfn.CONCAT("N Grigg-",(LEFT(B13,15)),"-",E13) -> N Grigg-APCO ALFREDTON -Travel NC - Fuel - | L13: I | M13: =IF(C13>0,C13,-D13) -> 112.79 | N13: T | R13: =LEN(K13) -> 43
A14: 45881 | B14: THINK ASIA T4 MELBOURNE A AUS | C14: 31.82 | E14: Airport Dinner | F14: G077 | G14: SALP | J14: =IF(F14>0,(_xlfn.CONCAT(F14,".",G14)),H14) -> G077.SALP | K14: =_xlfn.CONCAT("N Grigg-",(LEFT(B14,15)),"-",E14) -> N Grigg-THINK ASIA T4 M-Airport Dinner | L14: I | M14: =IF(C14>0,C14,-D14) -> 31.82 | N14: T | R14: =LEN(K14) -> 38
A15: 45881 | B15: MELBOURNE AIRPORT TULLAMARINE AUS | C15: 111 | E15: Travel NC | F15: G077 | G15: SALP | J15: =IF(F15>0,(_xlfn.CONCAT(F15,".",G15)),H15) -> G077.SALP | K15: =_xlfn.CONCAT("N Grigg-",(LEFT(B15,15)),"-",E15) -> N Grigg-MELBOURNE AIRPO-Travel NC | L15: I | M15: =IF(C15>0,C15,-D15) -> 111 | N15: T | R15: =LEN(K15) -> 33
A16: 45880 | B16: UBER *TRIP HELP.UBER.C 14518236738 AUS | C16: 12.05 | E16: Travel NC | F16: G077 | G16: SALP | J16: =IF(F16>0,(_xlfn.CONCAT(F16,".",G16)),H16) -> G077.SALP | K16: =_xlfn.CONCAT("N Grigg-",(LEFT(B16,15)),"-",E16) -> N Grigg-UBER *TRIP HELP-Travel NC | L16: I | M16: =IF(C16>0,C16,-D16) -> 12.05 | N16: T | R16: =LEN(K16) -> 33
A17: 45879 | B17: VIRGIN AU7954422641797 BRISBANE AUS | C17: 263.31 | E17: Flight Kal- Diggers | F17: G077 | G17: SALP | J17: =IF(F17>0,(_xlfn.CONCAT(F17,".",G17)),H17) -> G077.SALP | K17: =_xlfn.CONCAT("N Grigg-",(LEFT(B17,15)),"-",E17) -> N Grigg-VIRGIN AU795442-Flight Kal- Diggers | L17: I | M17: =IF(C17>0,C17,-D17) -> 263.31 | N17: T | R17: =LEN(K17) -> 43
A18: 45879 | B18: QANTAS0812374500543 NSW AUS | C18: 385.79 | E18: Flight perth - Diggers | F18: G077 | G18: SALP | J18: =IF(F18>0,(_xlfn.CONCAT(F18,".",G18)),H18) -> G077.SALP | K18: =_xlfn.CONCAT("N Grigg-",(LEFT(B18,15)),"-",E18) -> N Grigg-QANTAS081237450-Flight perth - Diggers | L18: I | M18: =IF(C18>0,C18,-D18) -> 385.79 | N18: T | R18: =LEN(K18) -> 46
A19: 45877 | B19: UBER *TRIP HELP.UBER.C 14518236738 AUS | C19: 8.94 | E19: Travel NC | F19: G077 | G19: SALP | J19: =IF(F19>0,(_xlfn.CONCAT(F19,".",G19)),H19) -> G077.SALP | K19: =_xlfn.CONCAT("N Grigg-",(LEFT(B19,15)),"-",E19) -> N Grigg-UBER *TRIP HELP-Travel NC | L19: I | M19: =IF(C19>0,C19,-D19) -> 8.94 | N19: T | R19: =LEN(K19) -> 33
A20: 45877 | B20: UBER *TRIP HELP.UBER.C 14518236738 AUS | C20: 173.35 | E20: Travel NC | F20: G077 | G20: SALP | J20: =IF(F20>0,(_xlfn.CONCAT(F20,".",G20)),H20) -> G077.SALP | K20: =_xlfn.CONCAT("N Grigg-",(LEFT(B20,15)),"-",E20) -> N Grigg-UBER *TRIP HELP-Travel NC | L20: I | M20: =IF(C20>0,C20,-D20) -> 173.35 | N20: T | R20: =LEN(K20) -> 33
A21: 45877 | B21: UBER *TRIP HELP.UBER.C 14518236738 AUS | C21: 31.53 | E21: Travel NC | F21: G077 | G21: SALP | J21: =IF(F21>0,(_xlfn.CONCAT(F21,".",G21)),H21) -> G077.SALP | K21: =_xlfn.CONCAT("N Grigg-",(LEFT(B21,15)),"-",E21) -> N Grigg-UBER *TRIP HELP-Travel NC | L21: I | M21: =IF(C21>0,C21,-D21) -> 31.53 | N21: T | R21: =LEN(K21) -> 33
A22: 45877 | B22: MondoMenu Long Neck Do MELBOURNE AUS | C22: 35.61 | E22: Food Airport | F22: G077 | G22: SALP | J22: =IF(F22>0,(_xlfn.CONCAT(F22,".",G22)),H22) -> G077.SALP | K22: =_xlfn.CONCAT("N Grigg-",(LEFT(B22,15)),"-",E22) -> N Grigg-MondoMenu Long -Food Airport | L22: I | M22: =IF(C22>0,C22,-D22) -> 35.61 | N22: T | R22: =LEN(K22) -> 36
A23: 45876 | B23: H.I. West Perth OPI West Perth AUS | C23: 282.67 | E23: Accom - Diggers NG | F23: G077 | G23: SALP | J23: =IF(F23>0,(_xlfn.CONCAT(F23,".",G23)),H23) -> G077.SALP | K23: =_xlfn.CONCAT("N Grigg-",(LEFT(B23,15)),"-",E23) -> N Grigg-H.I. West Perth-Accom - Diggers NG | L23: I | M23: =IF(C23>0,C23,-D23) -> 282.67 | N23: T | R23: =LEN(K23) -> 42
A24: 45876 | B24: BP KAMBALDA 6233 KAMBALDA EA AUS | C24: 64.1 | E24: Travel NC | F24: G077 | G24: SALP | J24: =IF(F24>0,(_xlfn.CONCAT(F24,".",G24)),H24) -> G077.SALP | K24: =_xlfn.CONCAT("N Grigg-",(LEFT(B24,15)),"-",E24) -> N Grigg-BP KAMBALDA 623-Travel NC | L24: I | M24: =IF(C24>0,C24,-D24) -> 64.1 | N24: T | R24: =LEN(K24) -> 33
... A68: 45860 | B68: UBER *TRIP Sydney AUS | C68: 13.52 | E68: Travel NC | F68: G077 | G68: SALP | J68: =IF(F68>0,(_xlfn.CONCAT(F68,".",G68)),H68) -> G077.SALP | K68: =_xlfn.CONCAT("N Grigg-",(LEFT(B68,15)),"-",E68) -> N Grigg-UBER *TRIP Sy-Travel NC | L68: I | M68: =IF(C68>0,C68,-D68) -> 13.52 | N68: T | R68: =LEN(K68) -> 33
A69: 45860 | B69: The Victoria Hotel ICP Melbourne AUS | C69: 8.12 | E69: Travel NC | F69: 1041 | G69: ENFE | J69: =IF(F69>0,(_xlfn.CONCAT(F69,".",G69)),H69) -> 1041.ENFE | K69: =_xlfn.CONCAT("N Grigg-",(LEFT(B69,15)),"-",E69) -> N Grigg-The Victoria Ho-Travel NC | L69: I | M69: =IF(C69>0,C69,-D69) -> 8.12 | N69: T | R69: =LEN(K69) -> 33
A70: 45860 | B70: The Victoria Hotel ICP Melbourne AUS | C70: 16.24 | E70: Cutting edge | F70: 1041 | G70: ENFE | J70: =IF(F70>0,(_xlfn.CONCAT(F70,".",G70)),H70) -> 1041.ENFE | K70: =_xlfn.CONCAT("N Grigg-",(LEFT(B70,15)),"-",E70) -> N Grigg-The Victoria Ho-Cutting edge | L70: I | M70: =IF(C70>0,C70,-D70) -> 16.24 | N70: T | R70: =LEN(K70) -> 37
A71: 45860 | B71: BALLARAT TAXI 131008 BALLARAT NO AUS | C71: 18.01 | E71: Travel NC | F71: G077 | G71: SALP | J71: =IF(F71>0,(_xlfn.CONCAT(F71,".",G71)),H71) -> G077.SALP | K71: =_xlfn.CONCAT("N Grigg-",(LEFT(B71,15)),"-",E71) -> N Grigg-BALLARAT TAXI 1-Travel NC | L71: I | M71: =IF(C71>0,C71,-D71) -> 18.01 | N71: T | R71: =LEN(K71) -> 33
A72: 45857 | B72: UBER *TRIP HELP.UBER.C 14518236738 AUS | C72: 11.39 | E72: Travel NC | F72: G077 | G72: SALP | J72: =IF(F72>0,(_xlfn.CONCAT(F72,".",G72)),H72) -> G077.SALP | K72: =_xlfn.CONCAT("N Grigg-",(LEFT(B72,15)),"-",E72) -> N Grigg-UBER *TRIP HELP-Travel NC | L72: I | M72: =IF(C72>0,C72,-D72) -> 11.39 | N72: T | R72: =LEN(K72) -> 33

Sheet S Jenkins
A1: Employee to code & narrate | J1: To be copied in to pronto
J2: Credit card Statement TOTAL | K2: 1682.17
J3: Subtotal | K3: =SUM(M9:M144) -> 1682.17
A4: Shayne Jenkins | J4: Variance Check | K4: =K2-K3 -> 0
A5: Reference | B5: =CONCATENATE(Header!$E$4,"Jenkins") -> MC-250816Jenkins | J5: EMPLOYEES DO NOT CHANGE
A6: Document Date | B6: =Header!$E$5 -> 45885 | E6: Credit card holder to add details
A8: Date | B8: Narrative | C8: Debit Amount | D8: Credit Amount | E8: Description | F8: Project No | G8: Cost Category | H8: GL account | J8: Account | K8: Reference | L8: Tax | M8: Amount | N8: Tax CODE | O8: TAX Amount (leave blank) | P8: CBS - Only if required | R8: limit 56charaters
A9: 45884 | B9: CASH ADVANCE FEE | C9: 6 | E9: Bank charge | F9: 1084 | G9: BFEE | J9: =IF(F9>0,(_xlfn.CONCAT(F9,".",G9)),H9) -> 1084.BFEE | K9: =_xlfn.CONCAT("S Jenkins-",(LEFT(B9,15)),"-",E9) -> S Jenkins-CASH ADVANCE FE-Bank charge | L9: I | M9: =IF(C9>0,C9,-D9) -> 6 | N9: F | Q9: CBS - needs to be pasted seperately | R9: =LEN(K9) -> 37
A10: 45884 | B10: ATM WDRL FEE BANK OF BENDIGO Alfredton Lu AUS | C10: 3.2 | E10: Bank charge | F10: 1084 | G10: BFEE | J10: =IF(F10>0,(_xlfn.CONCAT(F10,".",G10)),H10) -> 1084.BFEE | K10: =_xlfn.CONCAT("S Jenkins-",(LEFT(B10,15)),"-",E10) -> S Jenkins-ATM WDRL FEE BA-Bank charge | L10: I | M10: =IF(C10>0,C10,-D10) -> 3.2 | N10: F | R10: =LEN(K10) -> 37
