Workbook
Name TAX: #REF!

Sheet Header
D2: Batch | E2: 20251016
D3: Batch Desc | E3: Mastercard Invoices (November 2025)
D4: Reference | E4: MC-251116 | F4: `
D5: Document Date | E5: 45977
D6: Posting Date | E6: =E5 -> 45977
E13: LOG IN DETAILS
D15: User | E15: eTimesheet User
D16: Password | E16: gekko

Sheet S Baker
A1: Employee to code & narrate | J1: To be copied in to pronto
J2: Credit card Statement TOTAL
J3: Subtotal | K3: =SUM(M8:M143) -> 0
J4: Variance Check | K4: =K2-K3 -> 0
A5: Scott Baker
A6: Reference | B6: =CONCATENATE(Header!$E$4,"BAKER") -> MC-251116BAKER | J6: EMPLOYEES DO NOT CHANGE
A7: Document Date | B7: =Header!$E$5 -> 45977 | E7: Credit card holder to add details
A9: Date | B9: Narrative | C9: Debit Amount | D9: Credit Amount | E9: Description | F9: Project No | G9: Cost Category | H9: GL account | J9: Account | K9: Reference | L9: Tax | M9: Amount | N9: Tax CODE | O9: TAX Amount (leave blank) | P9: CBS - Only if required | R9: limit 56charaters
J10: =IF(F10>0,(_xlfn.CONCAT(F10,".",G10)),H10) -> 0 | K10: =_xlfn.CONCAT("S Baker-",B10,"-",E10) -> S Baker-- | L10: I | M10: =IF(C10>0,C10,-D10) -> 0 | N10: T | Q10: CBS - needs to be pasted seperately | R10: =LEN(K10) -> 9

Sheet S Barclay
A1: Employee to code & narrate | J1: To be copied in to pronto
J2: Credit card Statement TOTAL | K2: 237.48
J3: Subtotal | K3: =SUM(M8:M143) -> 237.48
J4: Variance Check | K4: =K2-K3 -> 0
A5: Simon Barclay
A6: Reference | B6: =CONCATENATE(Header!$E$4,"Barclay") -> MC-251116Barclay | J6: EMPLOYEES DO NOT CHANGE
A7: Document Date | B7: =Header!$E$5 -> 45977 | E7: Credit card holder to add details
A9: Date | B9: Narrative | C9: Debit Amount | D9: Credit Amount | E9: Description | F9: Project No | G9: Cost Category | H9: GL account | J9: Account | K9: Reference | L9: Tax | M9: Amount | N9: Tax CODE | O9: TAX Amount (leave blank) | P9: CBS - Only if required | R9: limit 56charaters
A10: 45968 | B10: Ink Station SYDNEY AUS | C10: 26.55 | D10: 0 | E10: Label roll | F10: 1053 | G10: cons | J10: =IF(F10>0,(_xlfn.CONCAT(F10,".",G10)),H10) -> 1053.cons | K10: =_xlfn.CONCAT("S Barclay-",E10,"-",B10) -> S Barclay-Label roll-Ink Station SYDNEY AUS | L10: I | M10: =IF(C10>0,C10,-D10) -> 26.55 | N10: T | Q10: CBS - needs to be pasted seperately | R10: =LEN(K10) -> 43
A11: 45975 | B11: OFFICEWORKS 0364 BALLARAT AUS | C11: 47.17 | D11: 0 | E11: stationary | F11: 1084 | G11: stat | J11: =IF(F11>0,(_xlfn.CONCAT(F11,".",G11)),H11) -> 1084.stat | K11: =_xlfn.CONCAT("S Barclay-",E11,"-",B11) -> S Barclay-stationary-OFFICEWORKS 0364 BALLARAT AUS | L11: I | M11: =IF(C11>0,C11,-D11) -> 47.17 | N11: T | Q11: CBS - needs to be pasted seperately | R11: =LEN(K11) -> 50
A12: 45958 | B12: BUNNINGS 329000 DELACOMBE AUS | C12: 49 | D12: 0 | E12: Tough Case | F12: 1073 | G12: tool | J12: =IF(F12>0,(_xlfn.CONCAT(F12,".",G12)),H12) -> 1073.tool | K12: =_xlfn.CONCAT("S Barclay-",E12,"-",B12) -> S Barclay-Tough Case-BUNNINGS 329000 DELACOMBE AUS | L12: I | M12: =IF(C12>0,C12,-D12) -> 49 | N12: T | Q12: CBS - needs to be pasted seperately | R12: =LEN(K12) -> 50
A13: 45961 | B13: WOOLWORTHS 3066 ALFREDTON AUS | C13: 114.76 | D13: 0 | E13: Pantry supplies | F13: 1084 | G13: cons | J13: =IF(F13>0,(_xlfn.CONCAT(F13,".",G13)),H13) -> 1084.cons | K13: =_xlfn.CONCAT("S Barclay-",E13,"-",B13) -> S Barclay-Pantry supplies-WOOLWORTHS 3066 ALFREDTON AUS | L13: I | M13: =IF(C13>0,C13,-D13) -> 114.76 | N13: T | Q13: CBS - needs to be pasted seperately | R13: =LEN(K13) -> 60

Sheet T Bell
A1: Employee to code & narrate | J1: To be copied in to pronto
J2: Credit card Statement TOTAL | K2: 1657.21
J3: Subtotal | K3: =SUM(M8:M143) -> 1657.21
J4: Variance Check | K4: =K2-K3 -> 0
A5: T Bell
A6: Reference | B6: =CONCATENATE(Header!$E$4,"Bell") -> MC-251116Bell | J6: EMPLOYEES DO NOT CHANGE
A7: Document Date | B7: =Header!$E$5 -> 45977 | E7: Credit card holder to add details
A9: Date | B9: Narrative | C9: Debit Amount | D9: Credit Amount | E9: Description | F9: Project No | G9: Cost Category | H9: GL account | J9: Account | K9: Reference | L9: Tax | M9: Amount | N9: Tax CODE | O9: TAX Amount (leave blank) | P9: CBS - Only if required | R9: limit 56charaters
A10: 16/11/2025 | B10: INTEREST CHARGES - CAS H | C10: 0.8 | D10: 0 | E10: Interest | F10: 1084 | G10: BFEE | J10: =IF(F10>0,(_xlfn.CONCAT(F10,".",G10)),H10) -> 1084.BFEE | K10: =_xlfn.CONCAT("T Bell-",E10,"-",B10) -> T Bell-Interest-INTEREST CHARGES - CAS H | L10: I | M10: =IF(C10>0,C10,-D10) -> 0.8 | N10: F | Q10: CBS - needs to be pasted seperately | R10: =LEN(K10) -> 40
A11: 16/10/2025 | B11: LEEDERVILLE MINI MAR LEEDERVILLE AUS | C11: 2.97 | D11: 0 | E11: Milk | F11: 1041 | G11: STAF | J11: =IF(F11>0,(_xlfn.CONCAT(F11,".",G11)),H11) -> 1041.STAF | K11: =_xlfn.CONCAT("T Bell-",E11,"-",B11) -> T Bell-Milk-LEEDERVILLE MINI MAR LEEDERVILLE AUS | L11: I | M11: =IF(C11>0,C11,-D11) -> 2.97 | N11: T | Q11: CBS - needs to be pasted seperately | R11: =LEN(K11) -> 48
A12: 10/11/2025 | B12: CASH ADVANCE FEE | C12: 5.93 | D12: 0 | E12: Fees | F12: 1084 | G12: BFEE | J12: =IF(F12>0,(_xlfn.CONCAT(F12,".",G12)),H12) -> 1084.BFEE | K12: =_xlfn.CONCAT("T Bell-",E12,"-",B12) -> T Bell-Fees-CASH ADVANCE FEE | L12: I | M12: =IF(C12>0,C12,-D12) -> 5.93 | N12: F | Q12: CBS - needs to be pasted seperately | R12: =LEN(K12) -> 28
A13: 9/11/2025 | B13: Panasonic Avionics Cor Irvine USA FRGN AMT: 3.99 U. S. DOLLAR | C13: 6.35 | D13: 0 | E13: Inflight Wifi on way to Turkey for IMCET | F13: G071 | G13: SALP | J13: =IF(F13>0,(_xlfn.CONCAT(F13,".",G13)),H13) -> G071.SALP | K13: =_xlfn.CONCAT("T Bell-",E13,"-",B13) -> T Bell-Inflight Wifi on way to Turkey for IMCET-Panasonic Avionics Cor Irvine USA FRGN AMT: 3.99 U. S. DOLLAR | L13: I | M13: =IF(C13>0,C13,-D13) -> 6.35 | N13: F | Q13: CBS - needs to be pasted seperately | R13: =LEN(K13) -> 110
A14: 9/11/2025 | B14: ZLR*WA Cellar Perth Airpo AUS | C14: 7 | D14: 0 | E14: Coffee at airport on way to Turkey for IMCET | F14: G071 | G14: SALP | J14: =IF(F14>0,(_xlfn.CONCAT(F14,".",G14)),H14) -> G071.SALP | K14: =_xlfn.CONCAT("T Bell-",E14,"-",B14) -> T Bell-Coffee at airport on way to Turkey for IMCET-ZLR*WA Cellar Perth Airpo AUS | L14: I | M14: =IF(C14>0,C14,-D14) -> 7 | N14: T | Q14: CBS - needs to be pasted seperately | R14: =LEN(K14) -> 81
A15: 7/11/2025 | B15: Holiday Inn Perth CBD Perth AUS | C15: 8.15 | D15: 0 | E15: Coffee/food at AGA Sukari meeting | F15: 1041 | G15: ENFE | J15: =IF(F15>0,(_xlfn.CONCAT(F15,".",G15)),H15) -> 1041.ENFE | K15: =_xlfn.CONCAT("T Bell-",E15,"-",B15) -> T Bell-Coffee/food at AGA Sukari meeting-Holiday Inn Perth CBD Perth AUS | L15: I | M15: =IF(C15>0,C15,-D15) -> 8.15 | N15: T | Q15: CBS - needs to be pasted seperately | R15: =LEN(K15) -> 72
A16: 4/11/2025 | B16: UBER* TRIP SYDNEY AUS | C16: 9 | D16: 0 | E16: Uber back from Northern Star Hemi meeting | F16: 1041 | G16: TRAV | J16: =IF(F16>0,(_xlfn.CONCAT(F16,".",G16)),H16) -> 1041.TRAV | K16: =_xlfn.CONCAT("T Bell-",E16,"-",B16) -> T Bell-Uber back from Northern Star Hemi meeting-UBER* TRIP SYDNEY AUS | L16: I | M16: =IF(C16>0,C16,-D16) -> 9 | N16: T | Q16: CBS - needs to be pasted seperately | R16: =LEN(K16) -> 70
A17: 5/11/2025 | B17: UBER *TRIP HELP.UBER.C 14518236738 AUS | C17: 9.39 | D17: 0 | E17: Uber to Northern Star Hemi meeting | F17: 1041 | G17: TRAV | J17: =IF(F17>0,(_xlfn.CONCAT(F17,".",G17)),H17) -> 1041.TRAV | K17: =_xlfn.CONCAT("T Bell-",E17,"-",B17) -> T Bell-Uber to Northern Star Hemi meeting-UBER *TRIP HELP.UBER.C 14518236738 AUS | L17: I | M17: =IF(C17>0,C17,-D17) -> 9.39 | N17: T | Q17: CBS - needs to be pasted seperately | R17: =LEN(K17) -> 80
A18: 23/10/2025 | B18: ZLR*BABYLON CAFE Leederville AUS | C18: 10.1 | D18: 0 | E18: Coffee with Bill S | F18: 1041 | G18: ENON | J18: =IF(F18>0,(_xlfn.CONCAT(F18,".",G18)),H18) -> 1041.ENON | K18: =_xlfn.CONCAT("T Bell-",E18,"-",B18) -> T Bell-Coffee with Bill S-ZLR*BABYLON CAFE Leederville AUS | L18: I | M18: =IF(C18>0,C18,-D18) -> 10.1 | N18: T | Q18: CBS - needs to be pasted seperately | R18: =LEN(K18) -> 58
A19: 30/10/2025 | B19: ZLR*BABYLON CAFE Leederville AUS | C19: 11.52 | D19: 0 | E19: Coffees for meeting | F19: 1041 | G19: ENON | J19: =IF(F19>0,(_xlfn.CONCAT(F19,".",G19)),H19) -> 1041.ENON | K19: =_xlfn.CONCAT("T Bell-",E19,"-",B19) -> T Bell-Coffees for meeting-ZLR*BABYLON CAFE Leederville AUS | L19: I | M19: =IF(C19>0,C19,-D19) -> 11.52 | N19: T | Q19: CBS - needs to be pasted seperately | R19: =LEN(K19) -> 59
A20: 9/11/2025 | B20: Hungry Jacks Perth AUS | C20: 11.7 | D20: 0 | E20: Food at airport on way to Turkey for IMCET | F20: G071 | G20: SALP | J20: =IF(F20>0,(_xlfn.CONCAT(F20,".",G20)),H20) -> G071.SALP | K20: =_xlfn.CONCAT("T Bell-",E20,"-",B20) -> T Bell-Food at airport on way to Turkey for IMCET-Hungry Jacks Perth AUS | L20: I | M20: =IF(C20>0,C20,-D20) -> 11.7 | N20: T | Q20: CBS - needs to be pasted seperately | R20: =LEN(K20) -> 72
A21: 28/10/2025 | B21: THE GOOD GROCER LEED LEEDERVILLE AUS | C21: 11.99 | D21: 0 | E21: Wednesday Lunch (Tim) | F21: 1084 | G21: ENON | J21: =IF(F21>0,(_xlfn.CONCAT(F21,".",G21)),H21) -> 1084.ENON | K21: =_xlfn.CONCAT("T Bell-",E21,"-",B21) -> T Bell-Wednesday Lunch (Tim)-THE GOOD GROCER LEED LEEDERVILLE AUS | L21: I | M21: =IF(C21>0,C21,-D21) -> 11.99 | N21: T | Q21: CBS - needs to be pasted seperately | R21: =LEN(K21) -> 65
A22: 9/11/2025 | B22: SPRINT-CASS PL T1 (E1) SINGAPORE SGP FRGN AMT: 9.90 SINGAPORE DOLLAR | C22: 12.11 | D22: 0 | E22: Travel adaptor for trip to Turkey, IMCET | F22: G071 | G22: SALP | J22: =IF(F22>0,(_xlfn.CONCAT(F22,".",G22)),H22) -> G071.SALP | K22: =_xlfn.CONCAT("T Bell-",E22,"-",B22) -> T Bell-Travel adaptor for trip to Turkey, IMCET-SPRINT-CASS PL T1 (E1) SINGAPORE SGP FRGN AMT: 9.90 SINGAPORE DOLLAR | L22: I | M22: =IF(C22>0,C22,-D22) -> 12.11 | N22: F | Q22: CBS - needs to be pasted seperately | R22: =LEN(K22) -> 117
A23: 26/10/2025 | B23: ROSSMOYNE IGA ROSSMOYNE AUS | C23: 13.35 | D23: 0 | E23: Milk / Coffee | F23: 1041 | G23: STAF | J23: =IF(F23>0,(_xlfn.CONCAT(F23,".",G23)),H23) -> 1041.STAF | K23: =_xlfn.CONCAT("T Bell-",E23,"-",B23) -> T Bell-Milk / Coffee-ROSSMOYNE IGA ROSSMOYNE AUS | L23: I | M23: =IF(C23>0,C23,-D23) -> 13.35 | N23: T | Q23: CBS - needs to be pasted seperately | R23: =LEN(K23) -> 48
A24: 16/10/2025 | B24: SQ *NOURISH KITCHEN & Leederville AUS | C24: 13.9 | D24: 0 | E24: Wednesday Lunch (Tim) | F24: 1084 | G24: ENON | J24: =IF(F24>0,(_xlfn.CONCAT(F24,".",G24)),H24) -> 1084.ENON | K24: =_xlfn.CONCAT("T Bell-",E24,"-",B24) -> T Bell-Wednesday Lunch (Tim)-SQ *NOURISH KITCHEN & Leederville AUS | L24: I | M24: =IF(C24>0,C24,-D24) -> 13.9 | N24: T | Q24: CBS - needs to be pasted seperately | R24: =LEN(K24) -> 66
A25: 31/10/2025 | B25: SQ *NOURISH KITCHEN & Leederville AUS | C25: 16.5 | D25: 0 | E25: Wednesday Lunch (Tim) | F25: 1084 | G25: ENON | J25: =IF(F25>0,(_xlfn.CONCAT(F25,".",G25)),H25) -> 1084.ENON | K25: =_xlfn.CONCAT("T Bell-",E25,"-",B25) -> T Bell-Wednesday Lunch (Tim)-SQ *NOURISH KITCHEN & Leederville AUS | L25: I | M25: =IF(C25>0,C25,-D25) -> 16.5 | N25: T | Q25: CBS - needs to be pasted seperately | R25: =LEN(K25) -> 66
A26: 10/11/2025 | B26: TT NET ANONIM STI ISTANBUL TUR FRGN AMT: 630.73 TURKISH LIRE | C26: 24.02 | D26: 0 | E26: Food/Drink on plane on way to Turkey for IMCET | F26: G071 | G26: SALP | J26: =IF(F26>0,(_xlfn.CONCAT(F26,".",G26)),H26) -> G071.SALP | K26: =_xlfn.CONCAT("T Bell-",E26,"-",B26) -> T Bell-Food/Drink on plane on way to Turkey for IMCET-TT NET ANONIM STI ISTANBUL TUR FRGN AMT: 630.73 TURKISH LIRE | L26: I | M26: =IF(C26>0,C26,-D26) -> 24.02 | N26: F | Q26: CBS - needs to be pasted seperately | R26: =LEN(K26) -> 115
A27: 7/11/2025 | B27: UBER *TRIP HELP.UBER.C 14518236738 AUS | C27: 28.56 | D27: 0 | E27: Uber to Sukari meeting | F27: 1041 | G27: TRAV | J27: =IF(F27>0,(_xlfn.CONCAT(F27,".",G27)),H27) -> 1041.TRAV | K27: =_xlfn.CONCAT("T Bell-",E27,"-",B27) -> T Bell-Uber to Sukari meeting-UBER *TRIP HELP.UBER.C 14518236738 AUS | L27: I | M27: =IF(C27>0,C27,-D27) -> 28.56 | N27: T | Q27: CBS - needs to be pasted seperately | R27: =LEN(K27) -> 68
A28: 24/10/2025 | B28: CELLARBRATIONS AT SHEL SHELLEY AUS | C28: 30 | D28: 0 | E28: Friday Drinks | F28: 1041 | G28: STAF | J28: =IF(F28>0,(_xlfn.CONCAT(F28,".",G28)),H28) -> 1041.STAF | K28: =_xlfn.CONCAT("T Bell-",E28,"-",B28) -> T Bell-Friday Drinks-CELLARBRATIONS AT SHEL SHELLEY AUS | L28: I | M28: =IF(C28>0,C28,-D28) -> 30 | N28: T | Q28: CBS - needs to be pasted seperately | R28: =LEN(K28) -> 55
A29: 8/11/2025 | B29: UBER *TRIP HELP.UBER.C 14518236738 AUS | C29: 30.74 | D29: 0 | E29: Uber home from Sukari meeting | F29: 1041 | G29: TRAV | J29: =IF(F29>0,(_xlfn.CONCAT(F29,".",G29)),H29) -> 1041.TRAV | K29: =_xlfn.CONCAT("T Bell-",E29,"-",B29) -> T Bell-Uber home from Sukari meeting-UBER *TRIP HELP.UBER.C 14518236738 AUS | L29: I | M29: =IF(C29>0,C29,-D29) -> 30.74 | N29: T | Q29: CBS - needs to be pasted seperately | R29: =LEN(K29) -> 75
A30: 4/11/2025 | B30: NIPPON FOOD ART PTY SUBIACO AUS | C30: 20.735 | D30: 0 | E30: Lunch with Marcus Locke - NSRL | F30: 1041 | G30: ENFE | J30: =IF(F30>0,(_xlfn.CONCAT(F30,".",G30)),H30) -> 1041.ENFE | K30: =_xlfn.CONCAT("T Bell-",E30,"-",B30) -> T Bell-Lunch with Marcus Locke - NSRL-NIPPON FOOD ART PTY SUBIACO AUS | L30: I | M30: =IF(C30>0,C30,-D30) -> 20.735 | N30: T | Q30: CBS - needs to be pasted seperately | R30: =LEN(K30) -> 69
A31: 4/11/2025 | B31: NIPPON FOOD ART PTY SUBIACO AUS | C31: 20.735 | D31: 0 | E31: Lunch with Marcus Locke - NSRL | F31: 1041 | G31: ENFN | J31: =IF(F31>0,(_xlfn.CONCAT(F31,".",G31)),H31) -> 1041.ENFN | K31: =_xlfn.CONCAT("T Bell-",E31,"-",B31) -> T Bell-Lunch with Marcus Locke - NSRL-NIPPON FOOD ART PTY SUBIACO AUS | L31: I | M31: =IF(C31>0,C31,-D31) -> 20.735 | N31: T | Q31: CBS - needs to be pasted seperately | R31: =LEN(K31) -> 69
A32: 10/11/2025 | B32: UBER *TRIP HELP.UBER.C 14518236738 AUS | C32: 42.25 | D32: 0 | E32: Uber to airport on way to Turkey for IMCET | F32: G071 | G32: SALP | J32: =IF(F32>0,(_xlfn.CONCAT(F32,".",G32)),H32) -> G071.SALP | K32: =_xlfn.CONCAT("T Bell-",E32,"-",B32) -> T Bell-Uber to airport on way to Turkey for IMCET-UBER *TRIP HELP.UBER.C 14518236738 AUS | L32: I | M32: =IF(C32>0,C32,-D32) -> 42.25 | N32: T | Q32: CBS - needs to be pasted seperately | R32: =LEN(K32) -> 88
A33: 9/11/2025 | B33: HEINEKEN WORLD BAR T1 SINGAPORE SGP FRGN AMT: 38.85 SINGAPORE DOLLAR | C33: 47.54 | D33: 0 | E33: Meal on way to Turkey for IMCET | F33: G071 | G33: SALP | J33: =IF(F33>0,(_xlfn.CONCAT(F33,".",G33)),H33) -> G071.SALP | K33: =_xlfn.CONCAT("T Bell-",E33,"-",B33) -> T Bell-Meal on way to Turkey for IMCET-HEINEKEN WORLD BAR T1 SINGAPORE SGP FRGN AMT: 38.85 SINGAPORE DOLLAR | L33: I | M33: =IF(C33>0,C33,-D33) -> 47.54 | N33: F | Q33: CBS - needs to be pasted seperately | R33: =LEN(K33) -> 108
A34: 27/10/2025 | B34: Hello Harry The Burge Leederville AUS | C34: 61 | D34: 0 | E34: Wednesday Lunch | F34: 1084 | G34: ENON | J34: =IF(F34>0,(_xlfn.CONCAT(F34,".",G34)),H34) -> 1084.ENON | K34: =_xlfn.CONCAT("T Bell-",E34,"-",B34) -> T Bell-Wednesday Lunch-Hello Harry The Burge Leederville AUS | L34: I | M34: =IF(C34>0,C34,-D34) -> 61 | N34: T | Q34: CBS - needs to be pasted seperately | R34: =LEN(K34) -> 60
A35: 20/10/2025 | B35: GYG Leederville Leederville AUS | C35: 65.5 | D35: 0 | E35: Wednesday Lunch | F35: 1084 | G35: ENON | J35: =IF(F35>0,(_xlfn.CONCAT(F35,".",G35)),H35) -> 1084.ENON | K35: =_xlfn.CONCAT("T Bell-",E35,"-",B35) -> T Bell-Wednesday Lunch-GYG Leederville Leederville AUS | L35: I | M35: =IF(C35>0,C35,-D35) -> 65.5 | N35: T | Q35: CBS - needs to be pasted seperately | R35: =LEN(K35) -> 54
A36: 18/10/2025 | B36: KATHMANDU PTY LTD SUCCESS AUS | C36: 83.99 | D36: 0 | E36: Personal issue with where credit card was stored which has now been resolved | F36: 1084 | G36: PERS | J36: =IF(F36>0,(_xlfn.CONCAT(F36,".",G36)),H36) -> 1084.PERS | K36: =_xlfn.CONCAT("T Bell-",E36,"-",B36) -> T Bell-Personal issue with where credit card was stored which has now been resolved-KATHMANDU PTY LTD SUCCESS AUS | L36: I | M36: =IF(C36>0,C36,-D36) -> 83.99 | N36: T | Q36: CBS - needs to be pasted seperately | R36: =LEN(K36) -> 113
A37: 22/10/2025 | B37: CELLARBRATIONS AT SHEL SHELLEY AUS | C37: 93 | D37: 0 | E37: Personal issue with where credit card was stored which has now been resolved | F37: 1084 | G37: PERS | J37: =IF(F37>0,(_xlfn.CONCAT(F37,".",G37)),H37) -> 1084.PERS | K37: =_xlfn.CONCAT("T Bell-",E37,"-",B37) -> T Bell-Personal issue with where credit card was stored which has now been resolved-CELLARBRATIONS AT SHEL SHELLEY AUS | L37: I | M37: =IF(C37>0,C37,-D37) -> 93 | N37: T | Q37: CBS - needs to be pasted seperately | R37: =LEN(K37) -> 118
A38: 19/10/2025 | B38: SOUTH SIDE POOL SERVIC CANNING VAL AUS | C38: 100 | D38: 0 | E38: Personal issue with where credit card was stored which has now been resolved | F38: 1084 | G38: PERS | J38: =IF(F38>0,(_xlfn.CONCAT(F38,".",G38)),H38) -> 1084.PERS | K38: =_xlfn.CONCAT("T Bell-",E38,"-",B38) -> T Bell-Personal issue with where credit card was stored which has now been resolved-SOUTH SIDE POOL SERVIC CANNING VAL AUS | L38: I | M38: =IF(C38>0,C38,-D38) -> 100 | N38: T | Q38: CBS - needs to be pasted seperately | R38: =LEN(K38) -> 122
A39: 24/10/2025 | B39: E-VISA TURKEY ANKARA TUR FRGN AMT: 67.95 U. S. DOLLAR | C39: 108.07 | D39: 0 | E39: Visa for Turkey - IMCET | F39: G071 | G39: SALP | J39: =IF(F39>0,(_xlfn.CONCAT(F39,".",G39)),H39) -> G071.SALP | K39: =_xlfn.CONCAT("T Bell-",E39,"-",B39) -> T Bell-Visa for Turkey - IMCET-E-VISA TURKEY ANKARA TUR FRGN AMT: 67.95 U. S. DOLLAR | L39: I | M39: =IF(C39>0,C39,-D39) -> 108.07 | N39: F | Q39: CBS - needs to be pasted seperately | R39: =LEN(K39) -> 85
A40: 3/11/2025 | B40: SQ *SEOUL HOPPERS Leederville AUS | C40: 137.9 | D40: 0 | E40: Wednesday Lunch | F40: 1084 | G40: ENON | J40: =IF(F40>0,(_xlfn.CONCAT(F40,".",G40)),H40) -> 1084.ENON | K40: =_xlfn.CONCAT("T Bell-",E40,"-",B40) -> T Bell-Wednesday Lunch-SQ *SEOUL HOPPERS Leederville AUS | L40: I | M40: =IF(C40>0,C40,-D40) -> 137.9 | N40: T | Q40: CBS - needs to be pasted seperately | R40: =LEN(K40) -> 56
A41: 13/11/2025 | B41: 7 MEHMET RESTAURANT ANTALYA TUR FRGN AMT: 3960.00 TURKISH LIRE | C41: 148.83 | D41: 0 | E41: Dinner in Turkey | F41: G071 | G41: SALP | J41: =IF(F41>0,(_xlfn.CONCAT(F41,".",G41)),H41) -> G071.SALP | K41: =_xlfn.CONCAT("T Bell-",E41,"-",B41) -> T Bell-Dinner in Turkey-7 MEHMET RESTAURANT ANTALYA TUR FRGN AMT: 3960.00 TURKISH LIRE | L41: I | M41: =IF(C41>0,C41,-D41) -> 148.83 | N41: F | Q41: CBS - needs to be pasted seperately | R41: =LEN(K41) -> 87
...

Sheet M Brown
A1: Employee to code & narrate | J1: To be copied in to pronto
J2: Credit card Statement TOTAL | K2: 1758.23
J3: Subtotal | K3: =SUM(M8:M143) -> 1758.23
J4: Variance Check | K4: =K2-K3 -> 0
A5: Michael Brown
A6: Reference | B6: =CONCATENATE(Header!$E$4,"Brown") -> MC-251116Brown | J6: EMPLOYEES DO NOT CHANGE
A7: Document Date | B7: =Header!$E$5 -> 45977 | E7: Credit card holder to add details
A9: Date | B9: Narrative | C9: Debit Amount | D9: Credit Amount | E9: Description | F9: Project No | G9: Cost Category | H9: GL account | J9: Account | K9: Reference | L9: Tax | M9: Amount | N9: Tax CODE | O9: TAX Amount (leave blank) | P9: CBS - Only if required | R9: limit 56charaters
A10: 45975 | B10: Ballarat Car Wash Pty Wendouree AUS | C10: 5.25 | D10: 0 | E10: Ute cleaning | F10: 1084 | G10: MVSR | J10: =IF(F10>0,(_xlfn.CONCAT(F10,".",G10)),H10) -> 1084.MVSR | K10: =_xlfn.CONCAT("M Brown-",E10,"-",B10) -> M Brown-Ute cleaning-Ballarat Car Wash Pty Wendouree AUS | L10: I | M10: =IF(C10>0,C10,-D10) -> 5.25 | N10: T | Q10: CBS - needs to be pasted seperately | R10: =LEN(K10) -> 56
A11: 45975 | B11: Ballarat Car Wash Pty Wendouree AUS | C11: 5.25 | D11: 0 | E11: Ute cleaning | F11: 1084 | G11: MVSR | J11: =IF(F11>0,(_xlfn.CONCAT(F11,".",G11)),H11) -> 1084.MVSR | K11: =_xlfn.CONCAT("M Brown-",E11,"-",B11) -> M Brown-Ute cleaning-Ballarat Car Wash Pty Wendouree AUS | L11: I | M11: =IF(C11>0,C11,-D11) -> 5.25 | N11: T | Q11: CBS - needs to be pasted seperately | R11: =LEN(K11) -> 56
A12: 45968 | B12: OFFICEWORKS 0364 BALLARAT AUS | C12: 9.98 | D12: 0 | E12: 2026 diary | F12: 1084 | G12: STAT | J12: =IF(F12>0,(_xlfn.CONCAT(F12,".",G12)),H12) -> 1084.STAT | K12: =_xlfn.CONCAT("M Brown-",E12,"-",B12) -> M Brown-2026 diary-OFFICEWORKS 0364 BALLARAT AUS | L12: I | M12: =IF(C12>0,C12,-D12) -> 9.98 | N12: T | Q12: CBS - needs to be pasted seperately | R12: =LEN(K12) -> 48
A13: 45957 | B13: Jaycar Ballarat Ballarat AUS | C13: 25 | D13: 0 | E13: Power lead for assay lab scales | F13: 1051 | G13: REPM | J13: =IF(F13>0,(_xlfn.CONCAT(F13,".",G13)),H13) -> 1051.REPM | K13: =_xlfn.CONCAT("M Brown-",E13,"-",B13) -> M Brown-Power lead for assay lab scales-Jaycar Ballarat Ballarat AUS | L13: I | M13: =IF(C13>0,C13,-D13) -> 25 | N13: T | Q13: CBS - needs to be pasted seperately | R13: =LEN(K13) -> 68
A14: 45946 | B14: RSEA PTY. LTD. BALLARAT CE AUS | C14: 29.99 | D14: 0 | E14: Hi Vis vests | F14: 1084 | G14: SPPE | J14: =IF(F14>0,(_xlfn.CONCAT(F14,".",G14)),H14) -> 1084.SPPE | K14: =_xlfn.CONCAT("M Brown-",E14,"-",B14) -> M Brown-Hi Vis vests-RSEA PTY. LTD. BALLARAT CE AUS | L14: I | M14: =IF(C14>0,C14,-D14) -> 29.99 | N14: T | Q14: CBS - needs to be pasted seperately | R14: =LEN(K14) -> 51
A15: 45973 | B15: BUNNINGS 329000 DELACOMBE AUS | C15: 36.6 | D15: 0 | E15: Masking tape and acetone | F15: 1084 | G15: REPM | J15: =IF(F15>0,(_xlfn.CONCAT(F15,".",G15)),H15) -> 1084.REPM | K15: =_xlfn.CONCAT("M Brown-",E15,"-",B15) -> M Brown-Masking tape and acetone-BUNNINGS 329000 DELACOMBE AUS | L15: I | M15: =IF(C15>0,C15,-D15) -> 36.6 | N15: T | Q15: CBS - needs to be pasted seperately | R15: =LEN(K15) -> 62
A16: 45960 | B16: BUNNINGS 730000 BALLARAT AUS | C16: 48.3 | D16: 0 | E16: masonite to repair ceiling B4 | F16: 1084 | G16: REPM | J16: =IF(F16>0,(_xlfn.CONCAT(F16,".",G16)),H16) -> 1084.REPM | K16: =_xlfn.CONCAT("M Brown-",E16,"-",B16) -> M Brown-masonite to repair ceiling B4-BUNNINGS 730000 BALLARAT AUS | L16: I | M16: =IF(C16>0,C16,-D16) -> 48.3 | N16: T | Q16: CBS - needs to be pasted seperately | R16: =LEN(K16) -> 66
A17: 45974 | B17: AWM WENDOUREE WENDOUREE AUS | C17: 49.88 | D17: 0 | E17: 15 amp lead for switch room | F17: 1084 | G17: REPM | J17: =IF(F17>0,(_xlfn.CONCAT(F17,".",G17)),H17) -> 1084.REPM | K17: =_xlfn.CONCAT("M Brown-",E17,"-",B17) -> M Brown-15 amp lead for switch room-AWM WENDOUREE WENDOUREE AUS | L17: I | M17: =IF(C17>0,C17,-D17) -> 49.88 | N17: T | Q17: CBS - needs to be pasted seperately | R17: =LEN(K17) -> 63
A18: 45957 | B18: BUNNINGS 329000 DELACOMBE AUS | C18: 67.86 | D18: 0 | E18: AAA and AA batteries | F18: 1084 | G18: REPM | J18: =IF(F18>0,(_xlfn.CONCAT(F18,".",G18)),H18) -> 1084.REPM | K18: =_xlfn.CONCAT("M Brown-",E18,"-",B18) -> M Brown-AAA and AA batteries-BUNNINGS 329000 DELACOMBE AUS | L18: I | M18: =IF(C18>0,C18,-D18) -> 67.86 | N18: T | Q18: CBS - needs to be pasted seperately | R18: =LEN(K18) -> 58
A19: 45972 | B19: AWM WENDOUREE WENDOUREE AUS | C19: 80.39 | D19: 0 | E19: Expanding foam B7 heater ducts | F19: 1084 | G19: REPM | J19: =IF(F19>0,(_xlfn.CONCAT(F19,".",G19)),H19) -> 1084.REPM | K19: =_xlfn.CONCAT("M Brown-",E19,"-",B19) -> M Brown-Expanding foam B7 heater ducts-AWM WENDOUREE WENDOUREE AUS | L19: I | M19: =IF(C19>0,C19,-D19) -> 80.39 | N19: T | Q19: CBS - needs to be pasted seperately | R19: =LEN(K19) -> 66
A20: 45947 | B20: BUNNINGS 730000 BALLARAT AUS | C20: 109.85 | D20: 0 | E20: Paint brush, stainless steal hooks | F20: 1084 | G20: REPM | J20: =IF(F20>0,(_xlfn.CONCAT(F20,".",G20)),H20) -> 1084.REPM | K20: =_xlfn.CONCAT("M Brown-",E20,"-",B20) -> M Brown-Paint brush, stainless steal hooks-BUNNINGS 730000 BALLARAT AUS | L20: I | M20: =IF(C20>0,C20,-D20) -> 109.85 | N20: T | Q20: CBS - needs to be pasted seperately | R20: =LEN(K20) -> 71
A21: 45952 | B21: Reddy Express 6744 Ballarat AUS | C21: 135.14 | D21: 0 | E21: Ute fuel | F21: 1084 | G21: MVPF | J21: =IF(F21>0,(_xlfn.CONCAT(F21,".",G21)),H21) -> 1084.MVPF | K21: =_xlfn.CONCAT("M Brown-",E21,"-",B21) -> M Brown-Ute fuel-Reddy Express 6744 Ballarat AUS | L21: I | M21: =IF(C21>0,C21,-D21) -> 135.14 | N21: T | Q21: CBS - needs to be pasted seperately | R21: =LEN(K21) -> 48
... A23: 45946 | B23: TOTAL TOOLS BALLARAT BALLARAT AUS | C23: 139 | D23: 0 | E23: Stud detector | F23: 1084 | G23: REPM | J23: =IF(F23>0,(_xlfn.CONCAT(F23,".",G23)),H23) -> 1084.REPM | K23: =_xlfn.CONCAT("M Brown-",E23,"-",B23) -> M Brown-Stud detector-TOTAL TOOLS BALLARAT BALLARAT AUS | L23: I | M23: =IF(C23>0,C23,-D23) -> 139 | N23: T | Q23: CBS - needs to be pasted seperately | R23: =LEN(K23) -> 55
A24: 45974 | B24: W J ROBSON AND SONS WENDOUREE AUS | C24: 149.63 | D24: 0 | E24: Window repair Mt Cog | F24: g125 | G24: misc | J24: =IF(F24>0,(_xlfn.CONCAT(F24,".",G24)),H24) -> g125.misc | K24: =_xlfn.CONCAT("M Brown-",E24,"-",B24) -> M Brown-Window repair Mt Cog-W J ROBSON AND SONS WENDOUREE AUS | L24: I | M24: =IF(C24>0,C24,-D24) -> 149.63 | N24: T | Q24: CBS - needs to be pasted seperately | R24: =LEN(K24) -> 62
A25: 45967 | B25: UNITED WENDOUREE WENDOUREE AUS | C25: 150.01 | D25: 0 | E25: Ute fuel | F25: 1084 | G25: MVPF | J25: =IF(F25>0,(_xlfn.CONCAT(F25,".",G25)),H25) -> 1084.MVPF | K25: =_xlfn.CONCAT("M Brown-",E25,"-",B25) -> M Brown-Ute fuel-UNITED WENDOUREE WENDOUREE AUS | L25: I | M25: =IF(C25>0,C25,-D25) -> 150.01 | N25: T | Q25: CBS - needs to be pasted seperately | R25: =LEN(K25) -> 47
A26: 45968 | B26: FIFTEEN NEEDLES GROUP WENDOUREE AUS | C26: 196 | D26: 0 | E26: Safety boots | F26: 1084 | G26: SPPE | J26: =IF(F26>0,(_xlfn.CONCAT(F26,".",G26)),H26) -> 1084.SPPE | K26: =_xlfn.CONCAT("M Brown-",E26,"-",B26) -> M Brown-Safety boots-FIFTEEN NEEDLES GROUP WENDOUREE AUS | L26: I | M26: =IF(C26>0,C26,-D26) -> 196 | N26: T | Q26: CBS - needs to be pasted seperately | R26: =LEN(K26) -> 56
A27: 45957 | B27: Industrial World BALLARAT AUS | C27: 381.1 | D27: 0 | E27: Assay Lab LM5 bearings | F27: 1051g | G27: REPM | J27: =IF(F27>0,(_xlfn.CONCAT(F27,".",G27)),H27) -> 1051g.REPM | K27: =_xlfn.CONCAT("M Brown-",E27,"-",B27) -> M Brown-Assay Lab LM5 bearings-Industrial World BALLARAT AUS | L27: I | M27: =IF(C27>0,C27,-D27) -> 381.1 | N27: T | Q27: CBS - needs to be pasted seperately | R27: =LEN(K27) -> 60

Sheet M Conroy
A1: Employee to code & narrate | J1: To be copied in to pronto
J2: Credit card Statement TOTAL | K2: 168.52
J3: Subtotal | K3: =SUM(M8:M143) -> 0
J4: Variance Check | K4: =K2-K3 -> 168.52
A5: Matthew Conroy
A6: Reference | B6: =CONCATENATE(Header!$E$4,"Conroy") -> MC-251116Conroy | J6: EMPLOYEES DO NOT CHANGE
A7: Document Date | B7: =Header!$E$5 -> 45977 | E7: Credit card holder to add details
A9: Date | B9: Narrative | C9: Debit Amount | D9: Credit Amount | E9: Description | F9: Project No | G9: Cost Category | H9: GL account | J9: Account | K9: Reference | L9: Tax | M9: Amount | N9: Tax CODE | O9: TAX Amount (leave blank) | P9: CBS - Only if required | R9: limit 56charaters
J10: =IF(F10>0,(_xlfn.CONCAT(F10,".",G10)),H10) -> 0 | K10: =_xlfn.CONCAT("M Conroy-",B10,"-",E10) -> M Conroy-- | L10: I | M10: =IF(C10>0,C10,-D10) -> 0 | N10: T | Q10: CBS - needs to be pasted seperately | R10: =LEN(K10) -> 10

Sheet G Delemontex
A1: Employee to code & narrate | J1: To be copied in to pronto
J2: Credit card Statement TOTAL | K2: 1280.11
J3: Subtotal | K3: =SUM(M8:M143) -> 1280.11
J4: Variance Check | K4: =K2-K3 -> 0
A5: Georges Delemontex
A6: Reference | B6: =CONCATENATE(Header!$E$4,"Delemontex") -> MC-251116Delemontex | J6: EMPLOYEES DO NOT CHANGE
A7: Document Date | B7: =Header!$E$5 -> 45977 | E7: Credit card holder to add details
A9: Date | B9: Narrative | C9: Debit Amount | D9: Credit Amount | E9: Description | F9: Project No | G9: Cost Category | H9: GL account | J9: Account | K9: Reference | L9: Tax | M9: Amount | N9: Tax CODE | O9: TAX Amount (leave blank) | P9: CBS - Only if required | R9: limit 56charaters
A10: 45960 | B10: BUNNINGS 730000 BALLARAT AUS | C10: 62.36 | D10: 0 | E10: R&D - Piping and fittings for trail of new lab digester pump | F10: 1060GE2 | G10: MISC | J10: =IF(F10>0,(_xlfn.CONCAT(F10,".",G10)),H10) -> 1060GE2.MISC | K10: =_xlfn.CONCAT("G Delemontex-",E10,"-",B10) -> G Delemontex-R&D - Piping and fittings for trail of new lab digester pump-BUNNINGS 730000 BALLARAT AUS | L10: I | M10: =IF(C10>0,C10,-D10) -> 62.36 | N10: T | Q10: CBS - needs to be pasted seperately | R10: =LEN(K10) -> 102
A11: 45954 | B11: Ballarat Plumbing Cen ALFREDTON AUS | C11: 87.75 | D11: 0 | E11: G24625 - AME - fittings for flowmeter installation to firm up total product flow | F11: 1060GE2 | G11: MISC | J11: =IF(F11>0,(_xlfn.CONCAT(F11,".",G11)),H11) -> 1060GE2.MISC | K11: =_xlfn.CONCAT("G Delemontex-",E11,"-",B11) -> G Delemontex-G24625 - AME - fittings for flowmeter installation to firm up total product flow-Ballarat Plumbing Cen ALFREDTON AUS | L11: I | M11: =IF(C11>0,C11,-D11) -> 87.75 | N11: T
A12: 45957 | B12: PUMPS AND PIPES SLACKS CREE AUS | C12: 1130 | D12: 0 | E12: R&D - PC Pump purchase for trail of new lab digester | F12: 1060GE2 | G12: MISC | J12: =IF(F12>0,(_xlfn.CONCAT(F12,".",G12)),H12) -> 1060GE2.MISC | K12: =_xlfn.CONCAT("G Delemontex-",E12,"-",B12) -> G Delemontex-R&D - PC Pump purchase for trail of new lab digester-PUMPS AND PIPES SLACKS CREE AUS | L12: I | M12: =IF(C12>0,C12,-D12) -> 1130 | N12: T

Sheet M Donadio
A1: Employee to code & narrate | J1: To be copied in to pronto
J2: Credit card Statement TOTAL | K2: 13283.13
J3: Subtotal | K3: =SUM(M8:M143) -> 13283.13
J4: Variance Check | K4: =K2-K3 -> 0
A5: Mark Donadio
A6: Reference | B6: =CONCATENATE(Header!$E$4,"Donadio") -> MC-251116Donadio | J6: EMPLOYEES DO NOT CHANGE
A7: Document Date | B7: =Header!$E$5 -> 45977 | E7: Credit card holder to add details
A9: Date | B9: Narrative | C9: Debit Amount | D9: Credit Amount | E9: Description | F9: Project No | G9: Cost Category | H9: GL account | J9: Account | K9: Reference | L9: Tax | M9: Amount | N9: Tax CODE | O9: TAX Amount (leave blank) | P9: CBS - Only if required | R9: limit 56charaters
A10: 45950 | B10: DNH*GODADDY#3927101700 SYDNEY AUS | C10: 30.45 | D10: 0 | E10: domain registration - www.Gaia-Evniro.com.au | F10: 1060GE2 | G10: MISC | J10: =IF(F10>0,(_xlfn.CONCAT(F10,".",G10)),H10) -> 1060GE2.MISC | K10: =_xlfn.CONCAT("M Donadio-",E10,"-",B10) -> M Donadio-domain registration - www.Gaia-Evniro.com.au-DNH*GODADDY#3927101700 SYDNEY AUS | L10: I | M10: =IF(C10>0,C10,-D10) -> 30.45 | N10: T | Q10: CBS - needs to be pasted seperately | R10: =LEN(K10) -> 88
A11: 45959 | B11: DNH*GODADDY#3934264793 SYDNEY AUS | C11: 40.9 | D11: 0 | E11: domain registration - gravityseparation | F11: 1084 | G11: WEBS | J11: =IF(F11>0,(_xlfn.CONCAT(F11,".",G11)),H11) -> 1084.WEBS | K11: =_xlfn.CONCAT("M Donadio-",E11,"-",B11) -> M Donadio-domain registration - gravityseparation-DNH*GODADDY#3934264793 SYDNEY AUS | L11: I | M11: =IF(C11>0,C11,-D11) -> 40.9 | N11: T | Q11: CBS - needs to be pasted seperately | R11: =LEN(K11) -> 83
A12: 45952 | B12: STARLINK INTERNET Sydney AUS | C12: 139 | D12: 0 | E12: Internet | F12: 1084 | G12: INTE | J12: =IF(F12>0,(_xlfn.CONCAT(F12,".",G12)),H12) -> 1084.INTE | K12: =_xlfn.CONCAT("M Donadio-",E12,"-",B12) -> M Donadio-Internet-STARLINK INTERNET Sydney AUS | L12: I | M12: =IF(C12>0,C12,-D12) -> 139 | N12: T | Q12: CBS - needs to be pasted seperately | R12: =LEN(K12) -> 47
A13: 45961 | B13: COLES 0628 BALLARAT AUS | C13: 215 | D13: 0 | E13: supplies | F13: 1084 | G13: STAF | J13: =IF(F13>0,(_xlfn.CONCAT(F13,".",G13)),H13) -> 1084.STAF | K13: =_xlfn.CONCAT("M Donadio-",E13,"-",B13) -> M Donadio-supplies-COLES 0628 BALLARAT AUS | L13: I | M13: =IF(C13>0,C13,-D13) -> 215 | N13: T | Q13: CBS - needs to be pasted seperately | R13: =LEN(K13) -> 42
A14: 45950 | B14: Hotel at Booking.com Sydney AUS | C14: 146.67 | D14: 0 | E14: accommodation for Cadell | F14: 1051 | G14: TRAI | J14: =IF(F14>0,(_xlfn.CONCAT(F14,".",G14)),H14) -> 1051.TRAI | K14: =_xlfn.CONCAT("M Donadio-",E14,"-",B14) -> M Donadio-accommodation for Cadell -Hotel at Booking.com Sydney AUS | L14: I | M14: =IF(C14>0,C14,-D14) -> 146.67 | N14: T | Q14: CBS - needs to be pasted seperately | R14: =LEN(K14) -> 67
A15: 46315 | B15: Hotel at Booking.com Sydney AUS | C15: 146.68 | D15: 0 | E15: accommodation for Oscar | F15: 1077 | G15: TRAI | J15: =IF(F15>0,(_xlfn.CONCAT(F15,".",G15)),H15) -> 1077.TRAI | K15: =_xlfn.CONCAT("M Donadio-",E15,"-",B15) -> M Donadio-accommodation for Oscar-Hotel at Booking.com Sydney AUS | L15: I | M15: =IF(C15>0,C15,-D15) -> 146.68 | N15: T | Q15: CBS - needs to be pasted seperately | R15: =LEN(K15) -> 65
A16: 45950 | B16: FlightCentre GiftCards South Brisb AUS | C16: 500 | D16: 0 | E16: farewell gift for Austell | F16: 1084 | G16: STAF | J16: =IF(F16>0,(_xlfn.CONCAT(F16,".",G16)),H16) -> 1084.STAF | K16: =_xlfn.CONCAT("M Donadio-",E16,"-",B16) -> M Donadio-farewell gift for Austell-FlightCentre GiftCards South Brisb AUS | L16: I | M16: =IF(C16>0,C16,-D16) -> 500 | N16: T | Q16: CBS - needs to be pasted seperately | R16: =LEN(K16) -> 74
A17: 45973 | B17: ANAESTHETIC GROUP BALLARAT AUS | C17: 685 | D17: 0 | E17: Loan to employee | F17: 1084 | G17: PERS | J17: =IF(F17>0,(_xlfn.CONCAT(F17,".",G17)),H17) -> 1084.PERS | K17: =_xlfn.CONCAT("M Donadio-",E17,"-",B17) -> M Donadio-Loan to employee-ANAESTHETIC GROUP BALLARAT AUS | L17: I | M17: =IF(C17>0,C17,-D17) -> 685 | N17: F | Q17: CBS - needs to be pasted seperately | R17: =LEN(K17) -> 57
A18: 45958 | B18: LinkedIn 10604917636 NORTH SYDNE AUS | C18: 1308.54 | D18: 0 | E18: LinkedIn recruiter | F18: 1084 | G18: RECR | J18: =IF(F18>0,(_xlfn.CONCAT(F18,".",G18)),H18) -> 1084.RECR | K18: =_xlfn.CONCAT("M Donadio-",E18,"-",B18) -> M Donadio-LinkedIn recruiter-LinkedIn 10604917636 NORTH SYDNE AUS | L18: I | M18: =IF(C18>0,C18,-D18) -> 1308.54 | N18: T | Q18: CBS - needs to be pasted seperately | R18: =LEN(K18) -> 65
A19: 45953 | B19: SMP*Major Roasts Ballarat No AUS | C19: 1607.59 | D19: 0 | E19: Wednesday lunch | F19: 1084 | G19: ENON | J19: =IF(F19>0,(_xlfn.CONCAT(F19,".",G19)),H19) -> 1084.ENON | K19: =_xlfn.CONCAT("M Donadio-",E19,"-",B19) -> M Donadio-Wednesday lunch-SMP*Major Roasts Ballarat No AUS | L19: I | M19: =IF(C19>0,C19,-D19) -> 1607.59 | N19: T | Q19: CBS - needs to be pasted seperately | R19: =LEN(K19) -> 58
A20: 45973 | B20: ST JOHN OF GOD BALLARA Perth AUS | C20: 2395 | D20: 0 | E20: Loan to employee | F20: 1084 | G20: PERS | J20: =IF(F20>0,(_xlfn.CONCAT(F20,".",G20)),H20) -> 1084.PERS | K20: =_xlfn.CONCAT("M Donadio-",E20,"-",B20) -> M Donadio-Loan to employee-ST JOHN OF GOD BALLARA Perth AUS | L20: I | M20: =IF(C20>0,C20,-D20) -> 2395 | N20: F | Q20: CBS - needs to be pasted seperately | R20: =LEN(K20) -> 59
A21: 45973 | B21: SP YETI CORPORATE SOUTH MELBO AUS | C21: 5450 | D21: 0 | E21: Gifst for staff celebrating OHS milestone | H21: 199999992320 | J21: =IF(F21>0,(_xlfn.CONCAT(F21,".",G21)),H21) -> 199999992320 | K21: =_xlfn.CONCAT("M Donadio-",E21,"-",B21) -> M Donadio-Gifst for staff celebrating OHS milestone-SP YETI CORPORATE SOUTH MELBO AUS | L21: I | M21: =IF(C21>0,C21,-D21) -> 5450 | N21: T | Q21: CBS - needs to be pasted seperately | R21: =LEN(K21) -> 85
A22: 45945 | B22: QANTAS | C22: 618.3 | D22: 0 | E22: QANTAS club membership for Wayne | F22: 1084 | G22: PREP | J22: =IF(F22>0,(_xlfn.CONCAT(F22,".",G22)),H22) -> 1084.PREP | K22: =_xlfn.CONCAT("M Donadio-",E22,"-",B22) -> M Donadio-QANTAS club membership for Wayne-QANTAS | L22: I | M22: =IF(C22>0,C22,-D22) -> 618.3 | N22: T | Q22: CBS - needs to be pasted seperately | R22: =LEN(K22) -> 49

Sheet L DUva
A1: Employee to code & narrate | J1: To be copied in to pronto
J2: Credit card Statement TOTAL | K2: 215.6
J3: Subtotal | K3: =SUM(M8:M143) -> 215.6
J4: Variance Check | K4: =K2-K3 -> 0
A5: Lisa Duva
A6: Reference | B6: =CONCATENATE(Header!$E$4,"DUVA") -> MC-251116DUVA | J6: EMPLOYEES DO NOT CHANGE
A7: Document Date | B7: =Header!$E$5 -> 45977 | E7: Credit card holder to add details
A9: Date | B9: Narrative | C9: Debit Amount | D9: Credit Amount | E9: Description | F9: Project No | G9: Cost Category | H9: GL account | J9: Account | K9: Reference | L9: Tax | M9: Amount | N9: Tax CODE | O9: TAX Amount (leave blank) | P9: CBS - Only if required | R9: limit 56charaters
A10: 45971 | B10: TSUKE BA LEEDERVILLE AUS | C10: 31 | D10: 0 | E10: Wednesday Lunch | F10: 1041 | G10: ENTON | J10: =IF(F10>0,(_xlfn.CONCAT(F10,".",G10)),H10) -> 1041.ENTON | K10: =_xlfn.CONCAT("L Duva-",E10,"-",B10) -> L Duva-Wednesday Lunch-TSUKE BA LEEDERVILLE AUS | L10: I | M10: =IF(C10>0,C10,-D10) -> 31 | N10: T | Q10: CBS - needs to be pasted seperately | R10: =LEN(K10) -> 47
A11: 45953 | B11: Live Payments Barangaroo AUS | C11: 92.3 | D11: 0 | E11: Taxi from Airport | F11: S17246 | G11: TRVT | J11: =IF(F11>0,(_xlfn.CONCAT(F11,".",G11)),H11) -> S17246.TRVT | K11: =_xlfn.CONCAT("L Duva-",E11,"-",B11) -> L Duva-Taxi from Airport-Live Payments Barangaroo AUS | L11: I | M11: =IF(C11>0,C11,-D11) -> 92.3 | N11: T | Q11: CBS - needs to be pasted seperately | R11: =LEN(K11) -> 53
A12: 45952 | B12: SPOTTO WA DARLINGHURS AUS | C12: 92.3 | D12: 0 | E12: Taxi to Airport | F12: S17246 | G12: TRVT | J12: =IF(F12>0,(_xlfn.CONCAT(F12,".",G12)),H12) -> S17246.TRVT | K12: =_xlfn.CONCAT("L Duva-",E12,"-",B12) -> L Duva- Taxi to Airport-SPOTTO WA DARLINGHURS AUS | L12: I | M12: =IF(C12>0,C12,-D12) -> 92.3 | N12: T | Q12: CBS - needs to be pasted seperately | R12: =LEN(K12) -> 49

Sheet A Edmondston
A1: Employee to code & narrate | J1: To be copied in to pronto
J2: Credit card Statement TOTAL | K2: 2897.18
J3: Subtotal | K3: =SUM(M10:M35) -> 2897.18
J4: Variance Check | K4: =K2-K3 -> 0
A5: Andrew Edmondston
A6: Reference | B6: =CONCATENATE(Header!$E$4,"Edmondston") -> MC-251116Edmondston | J6: EMPLOYEES DO NOT CHANGE
A7: Document Date | B7: =Header!$E$5 -> 45977 | E7: Credit card holder to add details
A9: Date | B9: Narrative | C9: Debit Amount | D9: Credit Amount | E9: Description | F9: Project No | G9: Cost Category | H9: GL account | J9: Account | K9: Reference | L9: Tax | M9: Amount | N9: Tax CODE | O9: TAX Amount (leave blank) | P9: CBS - Only if required | R9: limit 56charaters
A10: 45950 | B10: STATION REFRESHMEN BALLARAT AUS | C10: 5.95 | D10: 0 | E10: IMARC Food | F10: G081 | G10: SALP | J10: =IF(F10>0,(_xlfn.CONCAT(F10,".",G10)),H10) -> G081.SALP | K10: =_xlfn.CONCAT("A Edmondston-",E10,"-",B10) -> A Edmondston-IMARC Food-STATION REFRESHMEN BALLARAT AUS | L10: I | M10: =IF(C10>0,C10,-D10) -> 5.95 | N10: T | Q10: CBS - needs to be pasted seperately | R10: =LEN(K10) -> 55
A11: 45946 | B11: WOOLWORTHS 3309 WENDOUREE AUS | C11: 6 | D11: 0 | E11: Morning Tea - SDG Meeting | F11: 1084 | G11: ENON | J11: =IF(F11>0,(_xlfn.CONCAT(F11,".",G11)),H11) -> 1084.ENON | K11: =_xlfn.CONCAT("A Edmondston-",E11,"-",B11) -> A Edmondston-Morning Tea - SDG Meeting-WOOLWORTHS 3309 WENDOUREE AUS | L11: I | M11: =IF(C11>0,C11,-D11) -> 6 | N11: T | Q11: CBS - needs to be pasted seperately | R11: =LEN(K11) -> 73
A12: 45952 | B12: Brew Bros Cafe Sydney AUS | C12: 9.14 | D12: 0 | E12: IMARC Breakfast | F12: G081 | G12: SALP | J12: =IF(F12>0,(_xlfn.CONCAT(F12,".",G12)),H12) -> G081.SALP | K12: =_xlfn.CONCAT("A Edmondston-",E12,"-",B12) -> A Edmondston-IMARC Breakfast-Brew Bros Cafe Sydney AUS | L12: I | M12: =IF(C12>0,C12,-D12) -> 9.14 | N12: T | Q12: CBS - needs to be pasted seperately | R12: =LEN(K12) -> 54
A13: 45954 | B13: Ballarat City Council Ballarat Ce AUS | C13: 12 | D13: 0 | E13: Parking - Melbourne Mining Club | F13: 1084 | G13: MVPT | J13: =IF(F13>0,(_xlfn.CONCAT(F13,".",G13)),H13) -> 1084.MVPT | K13: =_xlfn.CONCAT("A Edmondston-",E13,"-",B13) -> A Edmondston-Parking - Melbourne Mining Club-Ballarat City Council Ballarat Ce AUS | L13: I | M13: =IF(C13>0,C13,-D13) -> 12 | N13: T | Q13: CBS - needs to be pasted seperately | R13: =LEN(K13) -> 82
A14: 45951 | B14: 347 KENT ST PTY LTD SYDNEY AUS | C14: 13.21 | D14: 0 | E14: IMARC Food | F14: G081 | G14: SALP | J14: =IF(F14>0,(_xlfn.CONCAT(F14,".",G14)),H14) -> G081.SALP | K14: =_xlfn.CONCAT("A Edmondston-",E14,"-",B14) -> A Edmondston-IMARC Food-347 KENT ST PTY LTD SYDNEY AUS | L14: I | M14: =IF(C14>0,C14,-D14) -> 13.21 | N14: T | Q14: CBS - needs to be pasted seperately | R14: =LEN(K14) -> 54
A15: 45950 | B15: UBER *TRIP HELP.UBER.C 14518236738 AUS | C15: 16.5 | D15: 0 | E15: IMARC - Taxi to station | F15: G081 | G15: SALP | J15: =IF(F15>0,(_xlfn.CONCAT(F15,".",G15)),H15) -> G081.SALP | K15: =_xlfn.CONCAT("A Edmondston-",E15,"-",B15) -> A Edmondston-IMARC - Taxi to station-UBER *TRIP HELP.UBER.C 14518236738 AUS | L15: I | M15: =IF(C15>0,C15,-D15) -> 16.5 | N15: T | Q15: CBS - needs to be pasted seperately | R15: =LEN(K15) -> 75
A16: 45946 | B16: BAKERS DELIGHT WENDOUR WENDOUREE AUS | C16: 19 | D16: 0 | E16: Morning Tea - SDG Meeting | F16: 1084 | G16: ENON | J16: =IF(F16>0,(_xlfn.CONCAT(F16,".",G16)),H16) -> 1084.ENON | K16: =_xlfn.CONCAT("A Edmondston-",E16,"-",B16) -> A Edmondston-Morning Tea - SDG Meeting-BAKERS DELIGHT WENDOUR WENDOUREE AUS | L16: I | M16: =IF(C16>0,C16,-D16) -> 19 | N16: T | Q16: CBS - needs to be pasted seperately | R16: =LEN(K16) -> 75
A17: 45953 | B17: TRANSPORTFORNSW TAP SYDNEY AUS | C17: 20.95 | D17: 0 | E17: IMARC - Train to Sydney City | F17: G081 | G17: SALP | J17: =IF(F17>0,(_xlfn.CONCAT(F17,".",G17)),H17) -> G081.SALP | K17: =_xlfn.CONCAT("A Edmondston-",E17,"-",B17) -> A Edmondston-IMARC - Train to Sydney City-TRANSPORTFORNSW TAP SYDNEY AUS | L17: I | M17: =IF(C17>0,C17,-D17) -> 20.95 | N17: T | Q17: CBS - needs to be pasted seperately | R17: =LEN(K17) -> 72
A18: 45952 | B18: ZLR*S2BISTR Mascot AUS | C18: 21.81 | D18: 0 | E18: IMARC Lunch | F18: G081 | G18: SALP | J18: =IF(F18>0,(_xlfn.CONCAT(F18,".",G18)),H18) -> G081.SALP | K18: =_xlfn.CONCAT("A Edmondston-",E18,"-",B18) -> A Edmondston-IMARC Lunch-ZLR*S2BISTR Mascot AUS | L18: I | M18: =IF(C18>0,C18,-D18) -> 21.81 | N18: T | Q18: CBS - needs to be pasted seperately | R18: =LEN(K18) -> 47
A19: 45951 | B19: TRANSPORTFORNSW TAP SYDNEY AUS | C19: 22.25 | D19: 0 | E19: IMARC - Train to Airport | F19: G081 | G19: SALP | J19: =IF(F19>0,(_xlfn.CONCAT(F19,".",G19)),H19) -> G081.SALP | K19: =_xlfn.CONCAT("A Edmondston-",E19,"-",B19) -> A Edmondston-IMARC - Train to Airport-TRANSPORTFORNSW TAP SYDNEY AUS | L19: I | M19: =IF(C19>0,C19,-D19) -> 22.25 | N19: T | Q19: CBS - needs to be pasted seperately | R19: =LEN(K19) -> 68
A20: 45950 | B20: Hotel CBD Sydney AUS | C20: 29.71 | D20: 0 | E20: IMARC - Food/Drinks | F20: G081 | G20: SALP | J20: =IF(F20>0,(_xlfn.CONCAT(F20,".",G20)),H20) -> G081.SALP | K20: =_xlfn.CONCAT("A Edmondston-",E20,"-",B20) -> A Edmondston-IMARC - Food/Drinks-Hotel CBD Sydney AUS | L20: I | M20: =IF(C20>0,C20,-D20) -> 29.71 | N20: T | Q20: CBS - needs to be pasted seperately | R20: =LEN(K20) -> 53
A21: 45950 | B21: Hotel CBD Sydney AUS | C21: 45.47 | D21: 0 | E21: IMARC Food/Drinks | F21: G081 | G21: SALP | J21: =IF(F21>0,(_xlfn.CONCAT(F21,".",G21)),H21) -> G081.SALP | K21: =_xlfn.CONCAT("A Edmondston-",E21,"-",B21) -> A Edmondston-IMARC Food/Drinks-Hotel CBD Sydney AUS | L21: I | M21: =IF(C21>0,C21,-D21) -> 45.47 | N21: T | Q21: CBS - needs to be pasted seperately | R21: =LEN(K21) -> 51
A22: 45951 | B22: Brew Bros Cafe Sydney AUS | C22: 45.68 | D22: 0 | E22: IMARC Food/Drinks | F22: G081 | G22: SALP | J22: =IF(F22>0,(_xlfn.CONCAT(F22,".",G22)),H22) -> G081.SALP | K22: =_xlfn.CONCAT("A Edmondston-",E22,"-",B22) -> A Edmondston-IMARC Food/Drinks-Brew Bros Cafe Sydney AUS | L22: I | M22: =IF(C22>0,C22,-D22) -> 45.68 | N22: T | Q22: CBS - needs to be pasted seperately | R22: =LEN(K22) -> 56
A23: 45970 | B23: SYMPOSIUM EVENTS PTY L MAIN BEACH AUS | C23: 50 | D23: 0 | E23: Australian Gold Conference Subscription | F23: 1084 | G23: CONF | J23: =IF(F23>0,(_xlfn.CONCAT(F23,".",G23)),H23) -> 1084.CONF | K23: =_xlfn.CONCAT("A Edmondston-",E23,"-",B23) -> A Edmondston-Australian Gold Conference Subscription-SYMPOSIUM EVENTS PTY L MAIN BEACH AUS | L23: I | M23: =IF(C23>0,C23,-D23) -> 50 | N23: T | Q23: CBS - needs to be pasted seperately | R23: =LEN(K23) -> 90
A24: 45952 | B24: ZLR*S2BISTR Mascot AUS | C24: 92.8 | D24: 0 | E24: IMARC Food | F24: G081 | G24: SALP | J24: =IF(F24>0,(_xlfn.CONCAT(F24,".",G24)),H24) -> G081.SALP | K24: =_xlfn.CONCAT("A Edmondston-",E24,"-",B24) -> A Edmondston-IMARC Food-ZLR*S2BISTR Mascot AUS | L24: I | M24: =IF(C24>0,C24,-D24) -> 92.8 | N24: T | Q24: CBS - needs to be pasted seperately | R24: =LEN(K24) -> 46
A25: 45952 | B25: Airport Shuttle Bus BAKERY HILL AUS | C25: 118 | D25: 0 | E25: IMARC Airport Shuttle Bus AE/NG | F25: G081 | G25: SALP | J25: =IF(F25>0,(_xlfn.CONCAT(F25,".",G25)),H25) -> G081.SALP | K25: =_xlfn.CONCAT("A Edmondston-",E25,"-",B25) -> A Edmondston-IMARC Airport Shuttle Bus AE/NG-Airport Shuttle Bus BAKERY HILL AUS | L25: I | M25: =IF(C25>0,C25,-D25) -> 118 | N25: T | Q25: CBS - needs to be pasted seperately | R25: =LEN(K25) -> 80
A26: 45947 | B26: THE LAKE VIEW Lake Wendou AUS | C26: 142.34 | D26: 0 | E26: Lunch AE, AL, MX, LC - Farewell lunch Austell | F26: 1084 | G26: ENFE | J26: =IF(F26>0,(_xlfn.CONCAT(F26,".",G26)),H26) -> 1084.ENFE | K26: =_xlfn.CONCAT("A Edmondston-",E26,"-",B26) -> A Edmondston-Lunch AE, AL, MX, LC - Farewell lunch Austell-THE LAKE VIEW Lake Wendou AUS | L26: I | M26: =IF(C26>0,C26,-D26) -> 142.34 | N26: T | Q26: CBS - needs to be pasted seperately | R26: =LEN(K26) -> 88
A27: 45973 | B27: 2 BLOKES COFFEE ROAST MOUNT HELEN AUS | C27: 185 | D27: 0 | E27: Coffee Beans | F27: 1084 | G27: STAF | J27: =IF(F27>0,(_xlfn.CONCAT(F27,".",G27)),H27) -> 1084.STAF | K27: =_xlfn.CONCAT("A Edmondston-",E27,"-",B27) -> A Edmondston-Coffee Beans-2 BLOKES COFFEE ROAST MOUNT HELEN AUS | L27: I | M27: =IF(C27>0,C27,-D27) -> 185 | N27: f | Q27: CBS - needs to be pasted seperately | R27: =LEN(K27) -> 64
A28: 45952 | B28: 2 BLOKES COFFEE ROAST MOUNT HELEN AUS | C28: 370 | D28: 0 | E28: Coffee Beans | F28: 1084 | G28: STAF | J28: =IF(F28>0,(_xlfn.CONCAT(F28,".",G28)),H28) -> 1084.STAF | K28: =_xlfn.CONCAT("A Edmondston-",E28,"-",B28) -> A Edmondston-Coffee Beans-2 BLOKES COFFEE ROAST MOUNT HELEN AUS | L28: I | M28: =IF(C28>0,C28,-D28) -> 370 | N28: f | Q28: CBS - needs to be pasted seperately | R28: =LEN(K28) -> 64
A29: 45951 | B29: JETSTARZT4MFK COLLINGWOOD AUS | C29: 1671.37 | D29: 0 | E29: IMARC - flights AE,NG | F29: G081 | G29: SALP | J29: =IF(F29>0,(_xlfn.CONCAT(F29,".",G29)),H29) -> G081.SALP | K29: =_xlfn.CONCAT("A Edmondston-",E29,"-",B29) -> A Edmondston-IMARC - flights AE,NG-JETSTARZT4MFK COLLINGWOOD AUS | L29: I | M29: =IF(C29>0,C29,-D29) -> 1671.37 | N29: T | Q29: CBS - needs to be pasted seperately | R29: =LEN(K29) -> 64

Sheet M Gort
A1: Employee to code & narrate | J1: To be copied in to pronto
J2: Credit card Statement TOTAL | K2: 138.59
J3: Subtotal | K3: =SUM(M8:M143) -> 138.59
J4: Variance Check | K4: =K2-K3 -> 0
A5: Marleen Gort
A6: Reference | B6: =CONCATENATE(Header!$E$4,"Gort") -> MC-251116Gort | J6: EMPLOYEES DO NOT CHANGE
A7: Document Date | B7: =Header!$E$5 -> 45977 | E7: Credit card holder to add details
A9: Date | B9: Narrative | C9: Debit Amount | D9: Credit Amount | E9: Description | F9: Project No | G9: Cost Category | H9: GL account | J9: Account | K9: Reference | L9: Tax | M9: Amount | N9: Tax CODE | O9: TAX Amount (leave blank) | P9: CBS - Only if required | R9: limit 56charaters
A10: 45968 | B10: Canva* 04693-7302731 Sydney AUS | C10: 41.6 | D10: 0 | E10: design software | F10: 1084 | G10: ITSW | J10: =IF(F10>0,(_xlfn.CONCAT(F10,".",G10)),H10) -> 1084.ITSW | K10: =_xlfn.CONCAT("M Gort-",E10,"-",B10) -> M Gort-design software-Canva* 04693-7302731 Sydney AUS | L10: I | M10: =IF(C10>0,C10,-D10) -> 41.6 | N10: T | Q10: CBS - needs to be pasted seperately | R10: =LEN(K10) -> 54
A11: 45956 | B11: Adobe Sydney AUS | C11: 96.99 | D11: 0 | E11: design software | F11: 1084 | G11: ITSW | J11: =IF(F11>0,(_xlfn.CONCAT(F11,".",G11)),H11) -> 1084.ITSW | K11: =_xlfn.CONCAT("M Gort-",E11,"-",B11) -> M Gort-design software-Adobe Sydney AUS | L11: I | M11: =IF(C11>0,C11,-D11) -> 96.99 | N11: T

Sheet N Grigg
A1: Employee to code & narrate | J1: To be copied in to pronto
J2: Credit card Statement TOTAL | K2: 4769.89
J3: Subtotal | K3: =SUM(M8:M143) -> 4769.89
J4: Variance Check | K4: =K2-K3 -> 0
A5: Nigel Grigg
A6: Reference | B6: =CONCATENATE(Header!$E$4,"Grigg") -> MC-251116Grigg | J6: EMPLOYEES DO NOT CHANGE
A7: Document Date | B7: =Header!$E$5 -> 45977 | E7: Credit card holder to add details
A9: Date | B9: Narrative | C9: Debit Amount | D9: Credit Amount | E9: Description | F9: Project No | G9: Cost Category | H9: GL account | J9: Account | K9: Reference | L9: Tax | M9: Amount | N9: Tax CODE | O9: TAX Amount (leave blank) | P9: CBS - Only if required | R9: limit 56charaters
A10: 45972 | B10: A N VENDING BALLARAT AUS | C10: 3.1 | D10: 0 | E10: food - cutting edge | F10: 1041 | G10: ENFE | J10: =IF(F10>0,(_xlfn.CONCAT(F10,".",G10)),H10) -> 1041.ENFE | K10: =_xlfn.CONCAT("N Grigg-",E10,"-",B10) -> N Grigg-food - cutting edge-A N VENDING BALLARAT AUS | L10: I | M10: =IF(C10>0,C10,-D10) -> 3.1 | N10: T | Q10: CBS - needs to be pasted seperately | R10: =LEN(K10) -> 53
A11: 45972 | B11: A N VENDING BALLARAT AUS | C11: 4.2 | D11: 0 | E11: food - cutting edge | F11: 1041 | G11: ENFE | J11: =IF(F11>0,(_xlfn.CONCAT(F11,".",G11)),H11) -> 1041.ENFE | K11: =_xlfn.CONCAT("N Grigg-",E11,"-",B11) -> N Grigg-food - cutting edge-A N VENDING BALLARAT AUS | L11: I | M11: =IF(C11>0,C11,-D11) -> 4.2 | N11: T | Q11: CBS - needs to be pasted seperately | R11: =LEN(K11) -> 53
A12: 45972 | B12: A N VENDING BALLARAT AUS | C12: 5.1 | D12: 0 | E12: food - cutting edge | F12: 1041 | G12: ENFE | J12: =IF(F12>0,(_xlfn.CONCAT(F12,".",G12)),H12) -> 1041.ENFE | K12: =_xlfn.CONCAT("N Grigg-",E12,"-",B12) -> N Grigg-food - cutting edge-A N VENDING BALLARAT AUS | L12: I | M12: =IF(C12>0,C12,-D12) -> 5.1 | N12: T | Q12: CBS - needs to be pasted seperately | R12: =LEN(K12) -> 53
A13: 45972 | B13: Hungry Jacks Melbourne ( AUS | C13: 14.75 | D13: 0 | E13: food - cutting edge | F13: 1041 | G13: ENFE | J13: =IF(F13>0,(_xlfn.CONCAT(F13,".",G13)),H13) -> 1041.ENFE | K13: =_xlfn.CONCAT("N Grigg-",E13,"-",B13) -> N Grigg-food - cutting edge-Hungry Jacks Melbourne ( AUS | L13: I | M13: =IF(C13>0,C13,-D13) -> 14.75 | N13: T | Q13: CBS - needs to be pasted seperately | R13: =LEN(K13) -> 57
A14: 45972 | B14: HI Melb Bourke SM ICP Melbourne AUS | C14: 14.99 | D14: 0 | E14: coffees -cutting edge | F14: 1041 | G14: ENFE | J14: =IF(F14>0,(_xlfn.CONCAT(F14,".",G14)),H14) -> 1041.ENFE | K14: =_xlfn.CONCAT("N Grigg-",E14,"-",B14) -> N Grigg-coffees -cutting edge-HI Melb Bourke SM ICP Melbourne AUS | L14: I | M14: =IF(C14>0,C14,-D14) -> 14.99 | N14: T | Q14: CBS - needs to be pasted seperately | R14: =LEN(K14) -> 65
A15: 45972 | B15: The Victoria Hotel ICP Melbourne AUS | C15: 20.3 | D15: 0 | E15: drinks -cutting edge - NG/BW | F15: 1041 | G15: ENFE | J15: =IF(F15>0,(_xlfn.CONCAT(F15,".",G15)),H15) -> 1041.ENFE | K15: =_xlfn.CONCAT("N Grigg-",E15,"-",B15) -> N Grigg-drinks -cutting edge - NG/BW-The Victoria Hotel ICP Melbourne AUS | L15: I | M15: =IF(C15>0,C15,-D15) -> 20.3 | N15: T | Q15: CBS - needs to be pasted seperately | R15: =LEN(K15) -> 73
A16: 45974 | B16: TICKETEK WEB Sydney AUS | C16: 268.5 | D16: 0 | E16: Ticket - AC | F16: 1041 | G16: ENFE | J16: =IF(F16>0,(_xlfn.CONCAT(F16,".",G16)),H16) -> 1041.ENFE | K16: =_xlfn.CONCAT("N Grigg-",E16,"-",B16) -> N Grigg-Ticket - AC-TICKETEK WEB Sydney AUS | L16: I | M16: =IF(C16>0,C16,-D16) -> 268.5 | N16: T | Q16: CBS - needs to be pasted seperately | R16: =LEN(K16) -> 43
A17: 45945 | B17: HO JIAK HAYMARKET | C17: 852.07 | D17: 0 | E17: Dinner | F17: G069 | G17: SALP | J17: =IF(F17>0,(_xlfn.CONCAT(F17,".",G17)),H17) -> G069.SALP | K17: =_xlfn.CONCAT("N Grigg-",E17,"-",B17) -> N Grigg-Dinner -HO JIAK HAYMARKET | L17: I | M17: =IF(C17>0,C17,-D17) -> 852.07 | N17: T | Q17: CBS - needs to be pasted seperately | R17: =LEN(K17) -> 34
A18: 45945 | B18: CROWN SYDNEY CIRQ BAR | C18: 71.22 | D18: 0 | E18: Drinks | F18: G069 | G18: SALP | J18: =IF(F18>0,(_xlfn.CONCAT(F18,".",G18)),H18) -> G069.SALP | K18: =_xlfn.CONCAT("N Grigg-",E18,"-",B18) -> N Grigg-Drinks-CROWN SYDNEY CIRQ BAR | L18: I | M18: =IF(C18>0,C18,-D18) -> 71.22 | N18: T | Q18: CBS - needs to be pasted seperately | R18: =LEN(K18) -> 36
A19: 45945 | B19: CROWN SYDNEY ICEBERGS | C19: 123.47 | D19: 0 | E19: Drinks/Lunch | F19: G069 | G19: SALP | J19: =IF(F19>0,(_xlfn.CONCAT(F19,".",G19)),H19) -> G069.SALP | K19: =_xlfn.CONCAT("N Grigg-",E19,"-",B19) -> N Grigg-Drinks/Lunch-CROWN SYDNEY ICEBERGS | L19: I | M19: =IF(C19>0,C19,-D19) -> 123.47 | N19: T | Q19: CBS - needs to be pasted seperately | R19: =LEN(K19) -> 42
A20: 45946 | B20: Crown Towers Sydney AUS | C20: 18.21 | D20: 0 | E20: drinks | F20: G069 | G20: SALP | J20: =IF(F20>0,(_xlfn.CONCAT(F20,".",G20)),H20) -> G069.SALP | K20: =_xlfn.CONCAT("N Grigg-",E20,"-",B20) -> N Grigg-drinks-Crown Towers Sydney AUS | L20: I | M20: =IF(C20>0,C20,-D20) -> 18.21 | N20: T | Q20: CBS - needs to be pasted seperately | R20: =LEN(K20) -> 38
A21: 45946 | B21: UBER *TRIP HELP.UBER.C 14518236738 AUS | C21: 23.8 | D21: 0 | E21: uber | F21: G069 | G21: SALP | J21: =IF(F21>0,(_xlfn.CONCAT(F21,".",G21)),H21) -> G069.SALP | K21: =_xlfn.CONCAT("N Grigg-",E21,"-",B21) -> N Grigg-uber-UBER *TRIP HELP.UBER.C 14518236738 AUS | L21: I | M21: =IF(C21>0,C21,-D21) -> 23.8 | N21: T | Q21: CBS - needs to be pasted seperately | R21: =LEN(K21) -> 51
A22: 45946 | B22: Crown Syd Icebergs Barangaroo AUS | C22: 72.32 | D22: 0 | E22: drinks/food | F22: G069 | G22: SALP | J22: =IF(F22>0,(_xlfn.CONCAT(F22,".",G22)),H22) -> G069.SALP | K22: =_xlfn.CONCAT("N Grigg-",E22,"-",B22) -> N Grigg-drinks/food-Crown Syd Icebergs Barangaroo AUS | L22: I | M22: =IF(C22>0,C22,-D22) -> 72.32 | N22: T | Q22: CBS - needs to be pasted seperately | R22: =LEN(K22) -> 53
A23: 45947 | B23: TRANSPORTFORNSW TAP SYDNEY AUS | C23: 22.25 | D23: 0 | E23: train airport | F23: G069 | G23: SALP | J23: =IF(F23>0,(_xlfn.CONCAT(F23,".",G23)),H23) -> G069.SALP | K23: =_xlfn.CONCAT("N Grigg-",E23,"-",B23) -> N Grigg-train airport-TRANSPORTFORNSW TAP SYDNEY AUS | L23: I | M23: =IF(C23>0,C23,-D23) -> 22.25 | N23: T | Q23: CBS - needs to be pasted seperately | R23: =LEN(K23) -> 52
A24: 45949 | B24: SGT*AppNibble Nicosia CYP FRGN AMT: 19.99 U. S. DOLLAR | C24: 31.97 | D24: 0 | E24: app cost | F24: 1084 | G24: ITSW | J24: =IF(F24>0,(_xlfn.CONCAT(F24,".",G24)),H24) -> 1084.ITSW | K24: =_xlfn.CONCAT("N Grigg-",E24,"-",B24) -> N Grigg-app cost-SGT*AppNibble Nicosia CYP FRGN AMT: 19.99 U. S. DOLLAR | L24: I | M24: =IF(C24>0,C24,-D24) -> 31.97 | N24: F | Q24: CBS - needs to be pasted seperately | R24: =LEN(K24) -> 72
A25: 45950 | B25: UBER *TRIP HELP.UBER.C 14518236738 AUS | C25: 16.36 | D25: 0 | E25: uber | F25: G069 | G25: SALP | J25: =IF(F25>0,(_xlfn.CONCAT(F25,".",G25)),H25) -> G069.SALP | K25: =_xlfn.CONCAT("N Grigg-",E25,"-",B25) -> N Grigg-uber -UBER *TRIP HELP.UBER.C 14518236738 AUS | L25: I | M25: =IF(C25>0,C25,-D25) -> 16.36 | N25: T | Q25: CBS - needs to be pasted seperately | R25: =LEN(K25) -> 52
A26: 45950 | B26: UBER *TRIP HELP.UBER.C 14518236738 AUS | C26: 28.31 | D26: 0 | E26: uber | F26: G069 | G26: SALP | J26: =IF(F26>0,(_xlfn.CONCAT(F26,".",G26)),H26) -> G069.SALP | K26: =_xlfn.CONCAT("N Grigg-",E26,"-",B26) -> N Grigg-uber-UBER *TRIP HELP.UBER.C 14518236738 AUS | L26: I | M26: =IF(C26>0,C26,-D26) -> 28.31 | N26: T | Q26: CBS - needs to be pasted seperately | R26: =LEN(K26) -> 51
A27: 45950 | B27: Hotel CBD Sydney AUS | C27: 65.89 | D27: 0 | E27: dinner AE/NG | F27: G081 | G27: SALP | J27: =IF(F27>0,(_xlfn.CONCAT(F27,".",G27)),H27) -> G081.SALP | K27: =_xlfn.CONCAT("N Grigg-",E27,"-",B27) -> N Grigg-dinner AE/NG-Hotel CBD Sydney AUS | L27: I | M27: =IF(C27>0,C27,-D27) -> 65.89 | N27: T | Q27: CBS - needs to be pasted seperately | R27: =LEN(K27) -> 41
A28: 45951 | B28: PLANAR RESTAURANT SYDNEY AUS | C28: 11.53 | D28: 0 | E28: drinks | F28: G081 | G28: SALP | J28: =IF(F28>0,(_xlfn.CONCAT(F28,".",G28)),H28) -> G081.SALP | K28: =_xlfn.CONCAT("N Grigg-",E28,"-",B28) -> N Grigg-drinks-PLANAR RESTAURANT SYDNEY AUS | L28: I | M28: =IF(C28>0,C28,-D28) -> 11.53 | N28: T | Q28: CBS - needs to be pasted seperately | R28: =LEN(K28) -> 43
A29: 45951 | B29: ICC Sydney Sydney AUS | C29: 16.8 | D29: 0 | E29: drinks | F29: G081 | G29: SALP | J29: =IF(F29>0,(_xlfn.CONCAT(F29,".",G29)),H29) -> G081.SALP | K29: =_xlfn.CONCAT("N Grigg-",E29,"-",B29) -> N Grigg-drinks-ICC Sydney Sydney AUS | L29: I | M29: =IF(C29>0,C29,-D29) -> 16.8 | N29: T | Q29: CBS - needs to be pasted seperately | R29: =LEN(K29) -> 36
A30: 45951 | B30: TRANSPORTFORNSW TAP SYDNEY AUS | C30: 22.25 | D30: 0 | E30: train | F30: G081 | G30: SALP | J30: =IF(F30>0,(_xlfn.CONCAT(F30,".",G30)),H30) -> G081.SALP | K30: =_xlfn.CONCAT("N Grigg-",E30,"-",B30) -> N Grigg-train -TRANSPORTFORNSW TAP SYDNEY AUS | L30: I | M30: =IF(C30>0,C30,-D30) -> 22.25 | N30: T | Q30: CBS - needs to be pasted seperately | R30: =LEN(K30) -> 45
A31: 45951 | B31: FratelliFreshDarling Sydney AUS | C31: 97.73 | D31: 0 | E31: dinner/drinks | F31: G081 | G31: SALP | J31: =IF(F31>0,(_xlfn.CONCAT(F31,".",G31)),H31) -> G081.SALP | K31: =_xlfn.CONCAT("N Grigg-",E31,"-",B31) -> N Grigg-dinner/drinks-FratelliFreshDarling Sydney AUS | L31: I | M31: =IF(C31>0,C31,-D31) -> 97.73 | N31: T | Q31: CBS - needs to be pasted seperately | R31: =LEN(K31) -> 53
A32: 45951 | B32: The Baxter Inn Sydney AUS | C32: 159.48 | D32: 0 | E32: dinner/drinks | F32: G081 | G32: SALP | J32: =IF(F32>0,(_xlfn.CONCAT(F32,".",G32)),H32) -> G081.SALP | K32: =_xlfn.CONCAT("N Grigg-",E32,"-",B32) -> N Grigg-dinner/drinks-The Baxter Inn Sydney AUS | L32: I | M32: =IF(C32>0,C32,-D32) -> 159.48 | N32: T | Q32: CBS - needs to be pasted seperately | R32: =LEN(K32) -> 47
A33: 45952 | B33: UBER *TRIP HELP.UBER.C 14518236738 AUS | C33: 20.35 | D33: 0 | E33: uber | F33: G081 | G33: SALP | J33: =IF(F33>0,(_xlfn.CONCAT(F33,".",G33)),H33) -> G081.SALP | K33: =_xlfn.CONCAT("N Grigg-",E33,"-",B33) -> N Grigg-uber-UBER *TRIP HELP.UBER.C 14518236738 AUS | L33: I | M33: =IF(C33>0,C33,-D33) -> 20.35 | N33: T | Q33: CBS - needs to be pasted seperately | R33: =LEN(K33) -> 51
A34: 45953 | B34: BENDIGO HOTEL FUND OP BENDIGO AUS | C34: 10.14 | D34: 0 | E34: drinks | F34: G119-05 | G34: SALP | J34: =IF(F34>0,(_xlfn.CONCAT(F34,".",G34)),H34) -> G119-05.SALP | K34: =_xlfn.CONCAT("N Grigg-",E34,"-",B34) -> N Grigg-drinks-BENDIGO HOTEL FUND OP BENDIGO AUS | L34: I | M34: =IF(C34>0,C34,-D34) -> 10.14 | N34: T | Q34: CBS - needs to be pasted seperately | R34: =LEN(K34) -> 48
A35: 45953 | B35: BENDIGO HOTEL FUND OP BENDIGO AUS | C35: 15.21 | D35: 0 | E35: drinks | F35: G119-05 | G35: SALP | J35: =IF(F35>0,(_xlfn.CONCAT(F35,".",G35)),H35) -> G119-05.SALP | K35: =_xlfn.CONCAT("N Grigg-",E35,"-",B35) -> N Grigg-drinks-BENDIGO HOTEL FUND OP BENDIGO AUS | L35: I | M35: =IF(C35>0,C35,-D35) -> 15.21 | N35: T | Q35: CBS - needs to be pasted seperately | R35: =LEN(K35) -> 48
A36: 45953 | B36: TRANSPORTFORNSW TAP SYDNEY AUS | C36: 20.95 | D36: 0 | E36: train to airport | F36: G081 | G36: SALP | J36: =IF(F36>0,(_xlfn.CONCAT(F36,".",G36)),H36) -> G081.SALP | K36: =_xlfn.CONCAT("N Grigg-",E36,"-",B36) -> N Grigg-train to airport-TRANSPORTFORNSW TAP SYDNEY AUS | L36: I | M36: =IF(C36>0,C36,-D36) -> 20.95 | N36: T | Q36: CBS - needs to be pasted seperately | R36: =LEN(K36) -> 55
... A45: 45954 | B45: Reddy Express 6821 Creswick AUS | C45: 151.98 | D45: 0 | E45: car/fuel | F45: G119-05 | G45: SALP | J45: =IF(F45>0,(_xlfn.CONCAT(F45,".",G45)),H45) -> G119-05.SALP | K45: =_xlfn.CONCAT("N Grigg-",E45,"-",B45) -> N Grigg-car/fuel-Reddy Express 6821 Creswick AUS | L45: I | M45: =IF(C45>0,C45,-D45) -> 151.98 | N45: T | Q45: CBS - needs to be pasted seperately | R45: =LEN(K45) -> 49
